Workbook

Sheet INV. FEB
A1: INVENTARIO
A2: PRODUCTO | B2: 01/02/25 INICIA | C2: 01/02/25 ENTRA | D2: 01/02/25 SALE | E2: 02/02/25 INICIA | F2: 02/02/25 ENTRA | G2: 02/02/25 SALE | H2: 03/02/25 INICIA | I2: 03/02/25 ENTRA | J2: 03/02/25 SALE | K2: 04/02/25 INICIA | L2: 04/02/25 ENTRA | M2: 04/02/25 SALE | N2: 06/02/25 INICIA | O2: 06/02/25 ENTRA | P2: 06/02/25 SALE | Q2: 07/02/25 INICIA | R2: 07/02/25 ENTRA | S2: 07/02/25 SALE | T2: 08/02/25 INICIA | U2: 08/02/25 SALE | V2: 09/02/25 INICIA | W2: 09/02/25 ENTRA | X2: 09/02/25 SALE | Y2: 10/02/25 INICIA | Z2: 10/02/25 SALE | AA2: 11/02/25 INICIA | AB2: 11/02/25 ENTRA | AC2: 11/02/25 SALE | AD2: 12/02/25 INICIA | AE2: 12/02/25 SALE | AF2: 13/02/25 INICIA | AG2: 13/02/25 SALE | AH2: 14/02/25 INICIA | AI2: 14/02/25 ENTRA | AJ2: 14/02/25 SALE | AK2: 15/02/25 INICIA | AL2: 15/02/25 ENTRA | AM2: 15/02/25 SALE | AN2: 16/02/25 INICIA | AO2: 16/02/25 ENTRA | AP2: 16/02/25 SALE | AQ2: 18/02/25 INICIA | AR2: 18/02/25 ENTRA | AS2: 18/02/25 SALE | AT2: 19/02/25 INICIA | AU2: 19/02/25 ENTRA | AV2: 19/02/25 SALE | AW2: 20/02/25 INICIA | AX2: 20/02/25 ENTRA | AY2: 20/02/25 SALE | AZ2: 21/02/25 INICIA | BA2: 21/02/25 ENTRA | BB2: 21/02/25 SALE | BC2: 22/02/25 INICIA | BD2: 22/02/25 ENTRA | BE2: 22/02/25 SALE | BF2: 23/02/25 INICIA | BG2: 23/02/25 ENTRA | BH2: 23/02/25 SALE | BI2: 24/02/25 INICIA | BJ2: 24/02/25 ENTRA | BK2: 24/02/25 SALE | BL2: 25/02/25 INICIA | BM2: 25/02/25 ENTRA | BN2: 25/02/25 SALE | BO2: 26/02/25 INICIA | BP2: 26/02/25 ENTRA | BQ2: 26/02/25 SALE | BR2: 27/02/25 INICIA | BS2: 27/02/25 ENTRA | BT2: 27/02/25 SALE | BU2: 28/02/25 INICIA | BV2: 28/02/25 ENTRA | BW2: 28/02/25 SALE | BX2: 01/03/25 INICIA
A3: AGUA X24 | B3: 24 | C3: 0 | D3: 3 | E3: =B3+C3-D3 -> 21 | F3: 0 | G3: 1 | H3: =E3+F3-G3 -> 20 | I3: 24 | J3: 0 | K3: =H3+I3-J3 -> 44 | L3: 0 | M3: 1 | N3: =K3+L3-M3 -> 43 | O3: 0 | P3: 5 | Q3: =N3+O3-P3 -> 38 | R3: 0 | S3: 0 | T3: =Q3+R3-S3 -> 38 | U3: 5 | V3: =T3-U3 -> 33 | W3: 0 | X3: 0 | Y3: =V3+W3-X3 -> 33 | Z3: 0 | AA3: =Y3-Z3 -> 33 | AB3: 0 | AC3: 0 | AD3: =AA3+AB3-AC3 -> 33 | AE3: 0 | AF3: =AD3-AE3 -> 33 | AG3: 0 | AH3: 32 | AI3: 0 | AJ3: 1 | AK3: =AH3+AI3-AJ3 -> 31 | AL3: 0 | AM3: 5 | AN3: =AK3+AL3-AM3 -> 26 | AO3: 0 | AP3: 0 | AQ3: =AN3+AO3-AP3 -> 26 | AR3: 0 | AS3: 0 | AT3: =AQ3+AR3-AS3 -> 26 | AU3: 0 | AV3: 1 | AW3: =AT3+AU3-AV3 -> 25 | AX3: 0 | AY3: 2 | AZ3: =AW3+AX3-AY3 -> 23 | BA3: 0 | BB3: 1 | BC3: =AZ3+BA3-BB3 -> 22 | BD3: 0 | BE3: 0 | BF3: =BC3+BD3-BE3 -> 22 | BG3: 0 | BH3: 0 | BI3: =BF3+BG3-BH3 -> 22 | BJ3: 0 | BK3: 0 | BL3: =BI3+BJ3-BK3 -> 22 | BM3: 0 | BN3: 1 | BO3: =BL3+BM3-BN3 -> 21 | BP3: 0 | BQ3: 0 | BR3: =BO3+BP3-BQ3 -> 21 | BS3: 0 | BT3: 6 | BU3: =BR3+BS3-BT3 -> 15 | BV3: 0 | BW3: 1 | BX3: =BU3+BV3-BW3 -> 14
A4: COCA COLA | B4: 20 | C4: 0 | D4: 0 | E4: =B4+C4-D4 -> 20 | F4: 0 | G4: 2 | H4: =E4+F4-G4 -> 18 | I4: 0 | J4: 1 | K4: =H4+I4-J4 -> 17 | L4: 0 | M4: 0 | N4: =K4+L4-M4 -> 17 | O4: 0 | P4: 1 | Q4: =N4+O4-P4 -> 16 | R4: 0 | S4: 1 | T4: =Q4+R4-S4 -> 15 | U4: 1 | V4: =T4-U4 -> 14 | W4: 0 | X4: 0 | Y4: =V4+W4-X4 -> 14 | Z4: 0 | AA4: =Y4-Z4 -> 14 | AB4: 0 | AC4: 0 | AD4: =AA4+AB4-AC4 -> 14 | AE4: 0 | AF4: =AD4-AE4 -> 14 | AG4: 0 | AH4: =AF4-AG4 -> 14 | AI4: 0 | AJ4: 2 | AK4: =AH4+AI4-AJ4 -> 12 | AL4: 0 | AM4: 0 | AN4: =AK4+AL4-AM4 -> 12 | AO4: 0 | AP4: 2 | AQ4: =AN4+AO4-AP4 -> 10 | AR4: 0 | AS4: 0 | AT4: =AQ4+AR4-AS4 -> 10 | AU4: 0 | AV4: 2 | AW4: =AT4+AU4-AV4 -> 8 | AX4: 0 | AY4: 2 | AZ4: =AW4+AX4-AY4 -> 6 | BA4: 0 | BB4: 1 | BC4: =AZ4+BA4-BB4 -> 5 | BD4: 0 | BE4: 0 | BF4: =BC4+BD4-BE4 -> 5 | BG4: 0 | BH4: 2 | BI4: =BF4+BG4-BH4 -> 3 | BJ4: 0 | BK4: 0 | BL4: =BI4+BJ4-BK4 -> 3 | BM4: 0 | BN4: 0 | BO4: =BL4+BM4-BN4 -> 3 | BP4: 12 | BQ4: 1 | BR4: =BO4+BP4-BQ4 -> 14 | BS4: 0 | BT4: 1 | BU4: =BR4+BS4-BT4 -> 13 | BV4: 0 | BW4: 1 | BX4: =BU4+BV4-BW4 -> 12
A5: GATORADE | B5: 1 | C5: 10 | D5: 0 | E5: =B5+C5-D5 -> 11 | F5: 0 | G5: 2 | H5: =E5+F5-G5 -> 9 | I5: 0 | J5: 0 | K5: =H5+I5-J5 -> 9 | L5: 0 | M5: 2 | N5: =K5+L5-M5 -> 7 | O5: 0 | P5: 6 | Q5: =N5+O5-P5 -> 1 | R5: 0 | S5: 0 | T5: =Q5+R5-S5 -> 1 | U5: 0 | V5: =T5-U5 -> 1 | W5: 0 | X5: 0 | Y5: =V5+W5-X5 -> 1 | Z5: 0 | AA5: =Y5-Z5 -> 1 | AB5: 0 | AC5: 1 | AD5: =AA5+AB5-AC5 -> 0 | AE5: 0 | AF5: =AD5-AE5 -> 0 | AG5: 0 | AH5: =AF5-AG5 -> 0 | AI5: 12 | AJ5: 1 | AK5: =AH5+AI5-AJ5 -> 11 | AL5: 0 | AM5: 1 | AN5: =AK5+AL5-AM5 -> 10 | AO5: 0 | AP5: 2 | AQ5: =AN5+AO5-AP5 -> 8 | AR5: 0 | AS5: 0 | AT5: =AQ5+AR5-AS5 -> 8 | AU5: 0 | AV5: 0 | AW5: =AT5+AU5-AV5 -> 8 | AX5: 0 | AY5: 0 | AZ5: =AW5+AX5-AY5 -> 8 | BA5: 0 | BB5: 1 | BC5: =AZ5+BA5-BB5 -> 7 | BD5: 0 | BE5: 1 | BF5: =BC5+BD5-BE5 -> 6 | BG5: 0 | BH5: 1 | BI5: =BF5+BG5-BH5 -> 5 | BJ5: 0 | BK5: 0 | BL5: =BI5+BJ5-BK5 -> 5 | BM5: 0 | BN5: 0 | BO5: =BL5+BM5-BN5 -> 5 | BP5: 12 | BQ5: 0 | BR5: =BO5+BP5-BQ5 -> 17 | BS5: 0 | BT5: 2 | BU5: =BR5+BS5-BT5 -> 15 | BV5: 0 | BW5: 1 | BX5: =BU5+BV5-BW5 -> 14
A6: SMIRNOFF | B6: 5 | C6: 0 | D6: 3 | E6: =B6+C6-D6 -> 2 | F6: 0 | G6: 0 | H6: =E6+F6-G6 -> 2 | I6: 2 | J6: 0 | K6: =H6+I6-J6 -> 4 | L6: 0 | M6: 0 | N6: =K6+L6-M6 -> 4 | O6: 0 | P6: 0 | Q6: =N6+O6-P6 -> 4 | R6: 0 | S6: 0 | T6: =Q6+R6-S6 -> 4 | U6: 0 | V6: =T6-U6 -> 4 | W6: 0 | X6: 0 | Y6: =V6+W6-X6 -> 4 | Z6: 0 | AA6: =Y6-Z6 -> 4 | AB6: 0 | AC6: 0 | AD6: =AA6+AB6-AC6 -> 4 | AE6: 0 | AF6: =AD6-AE6 -> 4 | AG6: 0 | AH6: =AF6-AG6 -> 4 | AI6: 0 | AJ6: 0 | AK6: =AH6+AI6-AJ6 -> 4 | AL6: 0 | AM6: 1 | AN6: =AK6+AL6-AM6 -> 3 | AO6: 0 | AP6: 0 | AQ6: =AN6+AO6-AP6 -> 3 | AR6: 0 | AS6: 0 | AT6: =AQ6+AR6-AS6 -> 3 | AU6: 0 | AV6: 0 | AW6: =AT6+AU6-AV6 -> 3 | AX6: 0 | AY6: 0 | AZ6: =AW6+AX6-AY6 -> 3 | BA6: 0 | BB6: 0 | BC6: =AZ6+BA6-BB6 -> 3 | BD6: 0 | BE6: 0 | BF6: =BC6+BD6-BE6 -> 3 | BG6: 0 | BH6: 0 | BI6: =BF6+BG6-BH6 -> 3 | BJ6: 0 | BK6: 0 | BL6: =BI6+BJ6-BK6 -> 3 | BM6: 0 | BN6: 0 | BO6: =BL6+BM6-BN6 -> 3 | BP6: 0 | BQ6: 0 | BR6: =BO6+BP6-BQ6 -> 3 | BS6: 0 | BT6: 0 | BU6: =BR6+BS6-BT6 -> 3 | BV6: 0 | BW6: 0 | BX6: =BU6+BV6-BW6 -> 3
A7: GASEOSA CUATRO | B7: 5 | C7: 0 | D7: 0 | E7: =B7+C7-D7 -> 5 | F7: 0 | G7: 1 | H7: =E7+F7-G7 -> 4 | I7: 0 | J7: 0 | K7: =H7+I7-J7 -> 4 | L7: 0 | M7: 0 | N7: =K7+L7-M7 -> 4 | O7: 0 | P7: 0 | Q7: =N7+O7-P7 -> 4 | R7: 0 | S7: 0 | T7: =Q7+R7-S7 -> 4 | U7: 0 | V7: =T7-U7 -> 4 | W7: 0 | X7: 0 | Y7: =V7+W7-X7 -> 4 | Z7: 0 | AA7: =Y7-Z7 -> 4 | AB7: 0 | AC7: 0 | AD7: =AA7+AB7-AC7 -> 4 | AE7: 0 | AF7: =AD7-AE7 -> 4 | AG7: 0 | AH7: =AF7-AG7 -> 4 | AI7: 0 | AJ7: 0 | AK7: =AH7+AI7-AJ7 -> 4 | AL7: 0 | AM7: 0 | AN7: =AK7+AL7-AM7 -> 4 | AO7: 0 | AP7: 0 | AQ7: =AN7+AO7-AP7 -> 4 | AR7: 0 | AS7: 0 | AT7: =AQ7+AR7-AS7 -> 4 | AU7: 0 | AV7: 0 | AW7: =AT7+AU7-AV7 -> 4 | AX7: 0 | AY7: 0 | AZ7: =AW7+AX7-AY7 -> 4 | BA7: 0 | BB7: 0 | BC7: =AZ7+BA7-BB7 -> 4 | BD7: 0 | BE7: 0 | BF7: =BC7+BD7-BE7 -> 4 | BG7: 0 | BH7: 0 | BI7: =BF7+BG7-BH7 -> 4 | BJ7: 0 | BK7: 0 | BL7: =BI7+BJ7-BK7 -> 4 | BM7: 0 | BN7: 0 | BO7: =BL7+BM7-BN7 -> 4 | BP7: 0 | BQ7: 0 | BR7: =BO7+BP7-BQ7 -> 4 | BS7: 0 | BT7: 0 | BU7: =BR7+BS7-BT7 -> 4 | BV7: 0 | BW7: 3 | BX7: =BU7+BV7-BW7 -> 1
A8: GASEOSA CANADA DRY | B8: 5 | C8: 0 | D8: 0 | E8: =B8+C8-D8 -> 5 | F8: 0 | G8: 0 | H8: =E8+F8-G8 -> 5 | I8: 0 | J8: 0 | K8: =H8+I8-J8 -> 5 | L8: 0 | M8: 0 | N8: =K8+L8-M8 -> 5 | O8: 0 | P8: 0 | Q8: =N8+O8-P8 -> 5 | R8: 0 | S8: 0 | T8: =Q8+R8-S8 -> 5 | U8: 0 | V8: =T8-U8 -> 5 | W8: 0 | X8: 0 | Y8: =V8+W8-X8 -> 5 | Z8: 0 | AA8: =Y8-Z8 -> 5 | AB8: 0 | AC8: 0 | AD8: =AA8+AB8-AC8 -> 5 | AE8: 0 | AF8: =AD8-AE8 -> 5 | AG8: 0 | AH8: =AF8-AG8 -> 5 | AI8: 0 | AJ8: 0 | AK8: =AH8+AI8-AJ8 -> 5 | AL8: 0 | AM8: 0 | AN8: =AK8+AL8-AM8 -> 5 | AO8: 0 | AP8: 0 | AQ8: =AN8+AO8-AP8 -> 5 | AR8: 0 | AS8: 0 | AT8: =AQ8+AR8-AS8 -> 5 | AU8: 0 | AV8: 0 | AW8: =AT8+AU8-AV8 -> 5 | AX8: 0 | AY8: 0 | AZ8: =AW8+AX8-AY8 -> 5 | BA8: 0 | BB8: 0 | BC8: =AZ8+BA8-BB8 -> 5 | BD8: 0 | BE8: 0 | BF8: =BC8+BD8-BE8 -> 5 | BG8: 0 | BH8: 0 | BI8: =BF8+BG8-BH8 -> 5 | BJ8: 0 | BK8: 0 | BL8: =BI8+BJ8-BK8 -> 5 | BM8: 0 | BN8: 0 | BO8: =BL8+BM8-BN8 -> 5 | BP8: 0 | BQ8: 0 | BR8: =BO8+BP8-BQ8 -> 5 | BS8: 0 | BT8: 1 | BU8: =BR8+BS8-BT8 -> 4 | BV8: 0 | BW8: 0 | BX8: =BU8+BV8-BW8 -> 4
A9: GASEOSA SHWEPPES | B9: 9 | C9: 0 | D9: 0 | E9: =B9+C9-D9 -> 9 | F9: 0 | G9: 0 | H9: =E9+F9-G9 -> 9 | I9: 0 | J9: 0 | K9: =H9+I9-J9 -> 9 | L9: 0 | M9: 0 | N9: =K9+L9-M9 -> 9 | O9: 0 | P9: 0 | Q9: =N9+O9-P9 -> 9 | R9: 0 | S9: 0 | T9: =Q9+R9-S9 -> 9 | U9: 0 | V9: =T9-U9 -> 9 | W9: 0 | X9: 0 | Y9: =V9+W9-X9 -> 9 | Z9: 0 | AA9: =Y9-Z9 -> 9 | AB9: 0 | AC9: 0 | AD9: =AA9+AB9-AC9 -> 9 | AE9: 0 | AF9: =AD9-AE9 -> 9 | AG9: 0 | AH9: =AF9-AG9 -> 9 | AI9: 0 | AJ9: 0 | AK9: =AH9+AI9-AJ9 -> 9 | AL9: 0 | AM9: 0 | AN9: =AK9+AL9-AM9 -> 9 | AO9: 0 | AP9: 0 | AQ9: =AN9+AO9-AP9 -> 9 | AR9: 0 | AS9: 0 | AT9: =AQ9+AR9-AS9 -> 9 | AU9: 0 | AV9: 0 | AW9: =AT9+AU9-AV9 -> 9 | AX9: 0 | AY9: 0 | AZ9: =AW9+AX9-AY9 -> 9 | BA9: 0 | BB9: 0 | BC9: =AZ9+BA9-BB9 -> 9 | BD9: 0 | BE9: 0 | BF9: =BC9+BD9-BE9 -> 9 | BG9: 0 | BH9: 0 | BI9: =BF9+BG9-BH9 -> 9 | BJ9: 0 | BK9: 0 | BL9: =BI9+BJ9-BK9 -> 9 | BM9: 0 | BN9: 0 | BO9: =BL9+BM9-BN9 -> 9 | BP9: 0 | BQ9: 0 | BR9: =BO9+BP9-BQ9 -> 9 | BS9: 0 | BT9: 0 | BU9: =BR9+BS9-BT9 -> 9 | BV9: 0 | BW9: 0 | BX9: =BU9+BV9-BW9 -> 9
A10: BRETAÑA | B10: 0 | C10: 0 | D10: 0 | E10: =B10+C10-D10 -> 0 | F10: 0 | G10: 0 | H10: =E10+F10-G10 -> 0 | I10: 0 | J10: 0 | K10: =H10+I10-J10 -> 0 | L10: 0 | M10: 0 | N10: =K10+L10-M10 -> 0 | O10: 0 | P10: 0 | Q10: =N10+O10-P10 -> 0 | R10: 0 | S10: 0 | T10: =Q10+R10-S10 -> 0 | U10: 0 | V10: =T10-U10 -> 0 | W10: 0 | X10: 0 | Y10: =V10+W10-X10 -> 0 | Z10: 0 | AA10: =Y10-Z10 -> 0 | AB10: 0 | AC10: 0 | AD10: =AA10+AB10-AC10 -> 0 | AE10: 0 | AF10: =AD10-AE10 -> 0 | AG10: 0 | AH10: =AF10-AG10 -> 0 | AI10: 0 | AJ10: 0 | AK10: =AH10+AI10-AJ10 -> 0 | AL10: 0 | AM10: 0 | AN10: =AK10+AL10-AM10 -> 0 | AO10: 0 | AP10: 0 | AQ10: =AN10+AO10-AP10 -> 0 | AR10: 0 | AS10: 0 | AT10: =AQ10+AR10-AS10 -> 0 | AU10: 0 | AV10: 0 | AW10: =AT10+AU10-AV10 -> 0 | AX10: 0 | AY10: 0 | AZ10: =AW10+AX10-AY10 -> 0 | BA10: 0 | BB10: 1 | BC10: =AZ10+BA10-BB10 -> -1 | BD10: 0 | BE10: 0 | BF10: =BC10+BD10-BE10 -> -1 | BG10: 0 | BH10: 0 | BI10: =BF10+BG10-BH10 -> -1 | BJ10: 0 | BK10: 0 | BL10: =BI10+BJ10-BK10 -> -1 | BM10: 0 | BN10: 0 | BO10: =BL10+BM10-BN10 -> -1 | BP10: 12 | BQ10: 0 | BR10: =BO10+BP10-BQ10 -> 11 | BS10: 0 | BT10: 0 | BU10: =BR10+BS10-BT10 -> 11 | BV10: 0 | BW10: 0 | BX10: =BU10+BV10-BW10 -> 11
A11: SPEED MAX | B11: 16 | C11: 0 | D11: 0 | E11: =B11+C11-D11 -> 16 | F11: 0 | G11: 0 | H11: =E11+F11-G11 -> 16 | I11: 0 | J11: 0 | K11: =H11+I11-J11 -> 16 | L11: 0 | M11: 0 | N11: =K11+L11-M11 -> 16 | O11: 0 | P11: 0 | Q11: =N11+O11-P11 -> 16 | R11: 0 | S11: 0 | T11: =Q11+R11-S11 -> 16 | U11: 0 | V11: =T11-U11 -> 16 | W11: 0 | X11: 0 | Y11: =V11+W11-X11 -> 16 | Z11: 0 | AA11: =Y11-Z11 -> 16 | AB11: 0 | AC11: 0 | AD11: =AA11+AB11-AC11 -> 16 | AE11: 0 | AF11: =AD11-AE11 -> 16 | AG11: 0 | AH11: =AF11-AG11 -> 16 | AI11: 0 | AJ11: 0 | AK11: =AH11+AI11-AJ11 -> 16 | AL11: 0 | AM11: 0 | AN11: =AK11+AL11-AM11 -> 16 | AO11: 0 | AP11: 2 | AQ11: =AN11+AO11-AP11 -> 14 | AR11: 0 | AS11: 0 | AT11: =AQ11+AR11-AS11 -> 14 | AU11: 0 | AV11: 0 | AW11: =AT11+AU11-AV11 -> 14 | AX11: 0 | AY11: 0 | AZ11: =AW11+AX11-AY11 -> 14 | BA11: 0 | BB11: 0 | BC11: =AZ11+BA11-BB11 -> 14 | BD11: 0 | BE11: 0 | BF11: =BC11+BD11-BE11 -> 14 | BG11: 0 | BH11: 0 | BI11: =BF11+BG11-BH11 -> 14 | BJ11: 0 | BK11: 0 | BL11: =BI11+BJ11-BK11 -> 14 | BM11: 0 | BN11: 0 | BO11: =BL11+BM11-BN11 -> 14 | BP11: 0 | BQ11: 0 | BR11: =BO11+BP11-BQ11 -> 14 | BS11: 0 | BT11: 0 | BU11: =BR11+BS11-BT11 -> 14 | BV11: 0 | BW11: 0 | BX11: =BU11+BV11-BW11 -> 14
A12: REDBULL | B12: 5 | C12: 0 | D12: 0 | E12: =B12+C12-D12 -> 5 | F12: 0 | G12: 0 | H12: =E12+F12-G12 -> 5 | I12: 0 | J12: 0 | K12: =H12+I12-J12 -> 5 | L12: 0 | M12: 0 | N12: =K12+L12-M12 -> 5 | O12: 0 | P12: 0 | Q12: =N12+O12-P12 -> 5 | R12: 0 | S12: 0 | T12: =Q12+R12-S12 -> 5 | U12: 0 | V12: =T12-U12 -> 5 | W12: 0 | X12: 0 | Y12: =V12+W12-X12 -> 5 | Z12: 0 | AA12: =Y12-Z12 -> 5 | AB12: 0 | AC12: 0 | AD12: =AA12+AB12-AC12 -> 5 | AE12: 0 | AF12: =AD12-AE12 -> 5 | AG12: 0 | AH12: =AF12-AG12 -> 5 | AI12: 0 | AJ12: 0 | AK12: =AH12+AI12-AJ12 -> 5 | AL12: 0 | AM12: 0 | AN12: =AK12+AL12-AM12 -> 5 | AO12: 0 | AP12: 0 | AQ12: =AN12+AO12-AP12 -> 5 | AR12: 0 | AS12: 0 | AT12: =AQ12+AR12-AS12 -> 5 | AU12: 0 | AV12: 0 | AW12: =AT12+AU12-AV12 -> 5 | AX12: 0 | AY12: 0 | AZ12: =AW12+AX12-AY12 -> 5 | BA12: 0 | BB12: 0 | BC12: =AZ12+BA12-BB12 -> 5 | BD12: 0 | BE12: 0 | BF12: =BC12+BD12-BE12 -> 5 | BG12: 0 | BH12: 0 | BI12: =BF12+BG12-BH12 -> 5 | BJ12: 0 | BK12: 0 | BL12: =BI12+BJ12-BK12 -> 5 | BM12: 0 | BN12: 0 | BO12: =BL12+BM12-BN12 -> 5 | BP12: 0 | BQ12: 0 | BR12: =BO12+BP12-BQ12 -> 5 | BS12: 0 | BT12: 0 | BU12: =BR12+BS12-BT12 -> 5 | BV12: 0 | BW12: 0 | BX12: =BU12+BV12-BW12 -> 5
A13: ELECTROLIT | B13: 10 | C13: 0 | D13: 0 | E13: =B13+C13-D13 -> 10 | F13: 0 | G13: 0 | H13: =E13+F13-G13 -> 10 | I13: 0 | J13: 0 | K13: =H13+I13-J13 -> 10 | L13: 0 | M13: 0 | N13: =K13+L13-M13 -> 10 | O13: 0 | P13: 0 | Q13: =N13+O13-P13 -> 10 | R13: 0 | S13: 0 | T13: =Q13+R13-S13 -> 10 | U13: 0 | V13: =T13-U13 -> 10 | W13: 0 | X13: 0 | Y13: =V13+W13-X13 -> 10 | Z13: 0 | AA13: =Y13-Z13 -> 10 | AB13: 0 | AC13: 0 | AD13: =AA13+AB13-AC13 -> 10 | AE13: 0 | AF13: =AD13-AE13 -> 10 | AG13: 0 | AH13: =AF13-AG13 -> 10 | AI13: 0 | AJ13: 0 | AK13: =AH13+AI13-AJ13 -> 10 | AL13: 0 | AM13: 1 | AN13: =AK13+AL13-AM13 -> 9 | AO13: 0 | AP13: 1 | AQ13: =AN13+AO13-AP13 -> 8 | AR13: 0 | AS13: 0 | AT13: =AQ13+AR13-AS13 -> 8 | AU13: 0 | AV13: 0 | AW13: =AT13+AU13-AV13 -> 8 | AX13: 0 | AY13: 0 | AZ13: =AW13+AX13-AY13 -> 8 | BA13: 0 | BB13: 0 | BC13: =AZ13+BA13-BB13 -> 8 | BD13: 0 | BE13: 1 | BF13: =BC13+BD13-BE13 -> 7 | BG13: 0 | BH13: 0 | BI13: =BF13+BG13-BH13 -> 7 | BJ13: 0 | BK13: 0 | BL13: =BI13+BJ13-BK13 -> 7 | BM13: 0 | BN13: 0 | BO13: =BL13+BM13-BN13 -> 7 | BP13: 0 | BQ13: 0 | BR13: =BO13+BP13-BQ13 -> 7 | BS13: 0 | BT13: 0 | BU13: =BR13+BS13-BT13 -> 7 | BV13: 0 | BW13: 0 | BX13: =BU13+BV13-BW13 -> 7
A14: POKER LATA | B14: 11 | C14: 0 | D14: 0 | E14: =B14+C14-D14 -> 11 | F14: 0 | G14: 0 | H14: =E14+F14-G14 -> 11 | I14: 0 | J14: 0 | K14: =H14+I14-J14 -> 11 | L14: 0 | M14: 0 | N14: =K14+L14-M14 -> 11 | O14: 0 | P14: 0 | Q14: =N14+O14-P14 -> 11 | R14: 0 | S14: 0 | T14: =Q14+R14-S14 -> 11 | U14: 1 | V14: =T14-U14 -> 10 | W14: 0 | X14: 0 | Y14: =V14+W14-X14 -> 10 | Z14: 0 | AA14: =Y14-Z14 -> 10 | AB14: 0 | AC14: 0 | AD14: =AA14+AB14-AC14 -> 10 | AE14: 0 | AF14: =AD14-AE14 -> 10 | AG14: 0 | AH14: =AF14-AG14 -> 10 | AI14: 0 | AJ14: 0 | AK14: =AH14+AI14-AJ14 -> 10 | AL14: 0 | AM14: 0 | AN14: =AK14+AL14-AM14 -> 10 | AO14: 0 | AP14: 0 | AQ14: =AN14+AO14-AP14 -> 10 | AR14: 0 | AS14: 0 | AT14: =AQ14+AR14-AS14 -> 10 | AU14: 0 | AV14: 0 | AW14: =AT14+AU14-AV14 -> 10 | AX14: 0 | AY14: 0 | AZ14: =AW14+AX14-AY14 -> 10 | BA14: 0 | BB14: 0 | BC14: =AZ14+BA14-BB14 -> 10 | BD14: 0 | BE14: 0 | BF14: =BC14+BD14-BE14 -> 10 | BG14: 0 | BH14: 0 | BI14: =BF14+BG14-BH14 -> 10 | BJ14: 0 | BK14: 0 | BL14: =BI14+BJ14-BK14 -> 10 | BM14: 0 | BN14: 0 | BO14: =BL14+BM14-BN14 -> 10 | BP14: 0 | BQ14: 0 | BR14: =BO14+BP14-BQ14 -> 10 | BS14: 0 | BT14: 0 | BU14: =BR14+BS14-BT14 -> 10 | BV14: 0 | BW14: 0 | BX14: =BU14+BV14-BW14 -> 10
A15: AGUILA LATA | B15: 0 | C15: 0 | D15: 0 | E15: =B15+C15-D15 -> 0 | F15: 0 | G15: 0 | H15: =E15+F15-G15 -> 0 | I15: 0 | J15: 0 | K15: =H15+I15-J15 -> 0 | L15: 0 | M15: 0 | N15: =K15+L15-M15 -> 0 | O15: 0 | P15: 0 | Q15: =N15+O15-P15 -> 0 | R15: 0 | S15: 0 | T15: =Q15+R15-S15 -> 0 | U15: 0 | V15: =T15-U15 -> 0 | W15: 0 | X15: 0 | Y15: =V15+W15-X15 -> 0 | Z15: 0 | AA15: =Y15-Z15 -> 0 | AB15: 0 | AC15: 0 | AD15: =AA15+AB15-AC15 -> 0 | AE15: 0 | AF15: =AD15-AE15 -> 0 | AG15: 0 | AH15: =AF15-AG15 -> 0 | AI15: 0 | AJ15: 0 | AK15: =AH15+AI15-AJ15 -> 0 | AL15: 0 | AM15: 0 | AN15: =AK15+AL15-AM15 -> 0 | AO15: 0 | AP15: 0 | AQ15: =AN15+AO15-AP15 -> 0 | AR15: 0 | AS15: 0 | AT15: =AQ15+AR15-AS15 -> 0 | AU15: 0 | AV15: 0 | AW15: =AT15+AU15-AV15 -> 0 | AX15: 0 | AY15: 0 | AZ15: =AW15+AX15-AY15 -> 0 | BA15: 0 | BB15: 0 | BC15: =AZ15+BA15-BB15 -> 0 | BD15: 0 | BE15: 0 | BF15: =BC15+BD15-BE15 -> 0 | BG15: 0 | BH15: 0 | BI15: =BF15+BG15-BH15 -> 0 | BJ15: 0 | BK15: 0 | BL15: =BI15+BJ15-BK15 -> 0 | BM15: 0 | BN15: 0 | BO15: =BL15+BM15-BN15 -> 0 | BP15: 0 | BQ15: 0 | BR15: =BO15+BP15-BQ15 -> 0 | BS15: 0 | BT15: 0 | BU15: =BR15+BS15-BT15 -> 0 | BV15: 0 | BW15: 0 | BX15: =BU15+BV15-BW15 -> 0
... A55: BOTELLA AGT. AMARILLO | B55: 1 | C55: 0 | D55: 0 | E55: =B55+C55-D55 -> 1 | F55: 0 | G55: 0 | H55: =E55+F55-G55 -> 1 | I55: 0 | J55: 0 | K55: =H55+I55-J55 -> 1 | L55: 0 | M55: 0 | N55: =K55+L55-M55 -> 1 | O55: 0 | P55: 0 | Q55: =N55+O55-P55 -> 1 | R55: 0 | S55: 0 | T55: =Q55+R55-S55 -> 1 | U55: 0 | V55: =T55-U55 -> 1 | W55: 0 | X55: 0 | Y55: =V55+W55-X55 -> 1 | Z55: 0 | AA55: =Y55-Z55 -> 1 | AB55: 0 | AC55: 0 | AD55: =AA55+AB55-AC55 -> 1 | AE55: 0 | AF55: =AD55-AE55 -> 1 | AG55: 0 | AH55: =AF55-AG55 -> 1 | AI55: 0 | AJ55: 0 | AK55: =AH55+AI55-AJ55 -> 1 | AL55: 0 | AM55: 0 | AN55: =AK55+AL55-AM55 -> 1 | AO55: 0 | AP55: 0 | AQ55: =AN55+AO55-AP55 -> 1 | AR55: 0 | AS55: 0 | AT55: =AQ55+AR55-AS55 -> 1 | AU55: 0 | AV55: 0 | AW55: =AT55+AU55-AV55 -> 1 | AX55: 0 | AY55: 0 | AZ55: =AW55+AX55-AY55 -> 1 | BA55: 0 | BB55: 0 | BC55: =AZ55+BA55-BB55 -> 1 | BD55: 0 | BE55: 0 | BF55: =BC55+BD55-BE55 -> 1 | BG55: 0 | BH55: 0 | BI55: =BF55+BG55-BH55 -> 1 | BJ55: 0 | BK55: 0 | BL55: =BI55+BJ55-BK55 -> 1 | BM55: 0 | BN55: 0 | BO55: =BL55+BM55-BN55 -> 1 | BP55: 0 | BQ55: 0 | BR55: =BO55+BP55-BQ55 -> 1 | BS55: 0 | BT55: 0 | BU55: =BR55+BS55-BT55 -> 1 | BV55: 0 | BW55: 0 | BX55: =BU55+BV55-BW55 -> 1
A56: STELLA | M56: 4 | N56: 0 | O56: 0 | P56: 0 | Q56: 0 | R56: 0 | S56: 0 | T56: =Q56+R56-S56 -> 0 | U56: 0 | V56: =T56-U56 -> 0 | W56: 0 | X56: 0 | Y56: =V56+W56-X56 -> 0 | Z56: 0 | AA56: =Y56-Z56 -> 0 | AB56: 0 | AC56: 0 | AD56: =AA56+AB56-AC56 -> 0 | AE56: 0 | AF56: =AD56-AE56 -> 0 | AG56: 0 | AH56: =AF56-AG56 -> 0

Sheet INV. ENE
A1: INVENTARIO | T1: DANIELA
A2: PRODUCTO | B2: 09/01/25 INICIA | C2: 09/01/25 SALE | D2: 10/01/25 INICIA | E2: 10/01/25 SALE | F2: 11/01/25 INICIA | G2: 11/01/25 SALE | H2: 12/01/25 INICIA | I2: 12/01/25 ENTRA | J2: 12/01/25 SALE | K2: 13/01/25 INICIA | L2: 13/01/25 ENTRA | M2: 13/01/25 SALE | N2: 14/01/25 INICIA | O2: 14/01/25 SALE | P2: 14/01/25 ENTRA | Q2: 15/01/25 INICIA | R2: 15/01/25 SALE | S2: 15/01/25 ENTRA | T2: 16/01/25 INICIA | U2: 16/01/25 SALE | V2: 16/01/25 ENTRA | W2: 17/01/25 INICIA | X2: 17/01/25 ENTRA | Y2: 17/01/25 SALE | Z2: 18/01/25 INICIA | AA2: 18/01/25 ENTRA | AB2: 18/01/25 SALE | AC2: 19/01/25 INICIA | AD2: 19/01/25 ENTRA | AE2: 19/01/25 SALE | AF2: 20/01/25 INICIA | AG2: 20/01/25 ENTRA | AH2: 20/01/25 SALE | AI2: 21/01/25 INICIA | AJ2: 21/01/25 ENTRA | AK2: 21/01/25 SALE | AL2: 22/01/25 INICIA | AM2: 22/01/25 ENTRA | AN2: 22/01/25 SALE | AO2: 23/01/25 INICIA | AP2: 23/01/25 ENTRA | AQ2: 23/01/25 SALE | AR2: 24/01/25 INICIA | AS2: 24/01/25 ENTRA | AT2: 24/01/25 SALE | AU2: 25/01/25 INICIA | AV2: 25/01/25 ENTRA | AW2: 25/01/25 SALE | AX2: 26/01/25 INICIA | AY2: 26/01/25 ENTRA | AZ2: 26/01/25 SALE | BA2: 27/01/25 INICIA | BB2: 27/01/25 ENTRA | BC2: 27/01/25 SALE | BD2: 28/01/25 INICIA | BE2: 28/01/25 ENTRA | BF2: 28/01/25 SALE | BG2: 29/01/25 INICIA | BH2: 29/01/25 ENTRA | BI2: 29/01/25 SALE | BJ2: 30/01/25 INICIA | BK2: 30/01/25 ENTRA | BL2: 30/01/25 SALE | BM2: 31/01/25 INICIA | BN2: 31/01/25 SALE | BO2: 01/02/25 INICIA
A3: AGUA X24 | B3: 66 | C3: 0 | D3: =B3-C3 -> 66 | E3: 0 | F3: =D3-E3 -> 66 | G3: 0 | H3: =F3-G3 -> 66 | I3: 0 | J3: 8 | K3: 57 | L3: 0 | M3: 2 | N3: =K3+L3-M3 -> 55 | O3: 2 | P3: 0 | Q3: =N3+P3-O3 -> 53 | R3: 1 | S3: 0 | T3: =Q3+S3-R3 -> 52 | U3: 0 | V3: 0 | W3: =T3+V3-U3 -> 52 | X3: 0 | Y3: 0 | Z3: =W3+X3-Y3 -> 52 | AA3: 0 | AB3: 1 | AC3: =Z3+AA3-AB3 -> 51 | AD3: 0 | AE3: 0 | AF3: =AC3+AD3-AE3 -> 51 | AG3: 0 | AH3: 0 | AI3: =AF3+AG3-AH3 -> 51 | AJ3: 0 | AK3: 5 | AL3: =AI3+AJ3-AK3 -> 46 | AM3: 0 | AN3: 0 | AO3: =AL3+AM3-AN3 -> 46 | AP3: 0 | AQ3: 12 | AR3: =AO3+AP3-AQ3 -> 34 | AS3: 0 | AT3: 0 | AU3: =AR3+AS3-AT3 -> 34 | AV3: 0 | AW3: 2 | AX3: =AU3+AV3-AW3 -> 32 | AY3: 0 | AZ3: 0 | BA3: =AX3+AY3-AZ3 -> 32 | BB3: 0 | BC3: 3 | BD3: =BA3+BB3-BC3 -> 29 | BE3: 0 | BF3: 0 | BG3: =BD3+BE3-BF3 -> 29 | BH3: 0 | BI3: 1 | BJ3: =BG3+BH3-BI3 -> 28 | BK3: 0 | BL3: 1 | BM3: =BJ3+BK3-BL3 -> 27 | BN3: 3 | BO3: =BM3-BN3 -> 24
A4: COCA COLA | B4: 28 | C4: 1 | D4: =B4-C4 -> 27 | E4: 0 | F4: =D4-E4 -> 27 | G4: 0 | H4: =F4-G4 -> 27 | I4: 0 | J4: 0 | K4: =H4+I4-J4 -> 27 | L4: 0 | M4: 0 | N4: =K4+L4-M4 -> 27 | O4: 0 | P4: 0 | Q4: =N4+P4-O4 -> 27 | R4: 0 | S4: 0 | T4: =Q4+S4-R4 -> 27 | U4: 0 | V4: 0 | W4: =T4+V4-U4 -> 27 | X4: 0 | Y4: 0 | Z4: =W4+X4-Y4 -> 27 | AA4: 0 | AB4: 0 | AC4: =Z4+AA4-AB4 -> 27 | AD4: 0 | AE4: 0 | AF4: =AC4+AD4-AE4 -> 27 | AG4: 0 | AH4: 0 | AI4: =AF4+AG4-AH4 -> 27 | AJ4: 0 | AK4: 0 | AL4: =AI4+AJ4-AK4 -> 27 | AM4: 0 | AN4: 0 | AO4: =AL4+AM4-AN4 -> 27 | AP4: 0 | AQ4: 0 | AR4: =AO4+AP4-AQ4 -> 27 | AS4: 0 | AT4: 0 | AU4: =AR4+AS4-AT4 -> 27 | AV4: 0 | AW4: 1 | AX4: =AU4+AV4-AW4 -> 26 | AY4: 0 | AZ4: 1 | BA4: =AX4+AY4-AZ4 -> 25 | BB4: 0 | BC4: 2 | BD4: =BA4+BB4-BC4 -> 23 | BE4: 0 | BF4: 0 | BG4: =BD4+BE4-BF4 -> 23 | BH4: 0 | BI4: 0 | BJ4: =BG4+BH4-BI4 -> 23 | BK4: 0 | BL4: 0 | BM4: =BJ4+BK4-BL4 -> 23 | BN4: 0 | BO4: =BM4-BN4 -> 23
A5: GATORADE | B5: 5 | C5: 0 | D5: =B5-C5 -> 5 | E5: 1 | F5: =D5-E5 -> 4 | G5: 0 | H5: =F5-G5 -> 4 | I5: 0 | J5: 1 | K5: =H5+I5-J5 -> 3 | L5: 1 | M5: 4 | N5: =K5+L5-M5 -> 0 | O5: 0 | P5: 11 | Q5: =N5+P5-O5 -> 11 | R5: 2 | S5: 0 | T5: =Q5+S5-R5 -> 9 | U5: 1 | V5: 0 | W5: =T5+V5-U5 -> 8 | X5: 0 | Y5: 0 | Z5: =W5+X5-Y5 -> 8 | AA5: 0 | AB5: 1 | AC5: =Z5+AA5-AB5 -> 7 | AD5: 0 | AE5: 0 | AF5: =AC5+AD5-AE5 -> 7 | AG5: 0 | AH5: 2 | AI5: =AF5+AG5-AH5 -> 5 | AJ5: 0 | AK5: 0 | AL5: =AI5+AJ5-AK5 -> 5 | AM5: 0 | AN5: 0 | AO5: =AL5+AM5-AN5 -> 5 | AP5: 0 | AQ5: 0 | AR5: =AO5+AP5-AQ5 -> 5 | AS5: 0 | AT5: 1 | AU5: =AR5+AS5-AT5 -> 4 | AV5: 0 | AW5: 0 | AX5: =AU5+AV5-AW5 -> 4 | AY5: 0 | AZ5: 0 | BA5: =AX5+AY5-AZ5 -> 4 | BB5: 0 | BC5: 0 | BD5: =BA5+BB5-BC5 -> 4 | BE5: 0 | BF5: 2 | BG5: =BD5+BE5-BF5 -> 2 | BH5: 0 | BI5: 0 | BJ5: =BG5+BH5-BI5 -> 2 | BK5: 0 | BL5: 0 | BM5: =BJ5+BK5-BL5 -> 2 | BN5: 1 | BO5: =BM5-BN5 -> 1
A6: SMIRNOFF | B6: 4 | C6: 0 | D6: =B6-C6 -> 4 | E6: 0 | F6: =D6-E6 -> 4 | G6: 0 | H6: =F6-G6 -> 4 | I6: 0 | J6: 0 | K6: =H6+I6-J6 -> 4 | L6: 7 | M6: 3 | N6: =K6+L6-M6 -> 8 | O6: 0 | P6: 0 | Q6: =N6+P6-O6 -> 8 | S6: 0 | T6: =Q6+S6-R6 -> 8 | U6: 0 | V6: 0 | W6: =T6+V6-U6 -> 8 | X6: 0 | Y6: 0 | Z6: =W6+X6-Y6 -> 8 | AA6: 0 | AB6: 1 | AC6: =Z6+AA6-AB6 -> 7 | AD6: 0 | AE6: 0 | AF6: =AC6+AD6-AE6 -> 7 | AG6: 0 | AH6: 0 | AI6: =AF6+AG6-AH6 -> 7 | AJ6: 0 | AK6: 0 | AL6: =AI6+AJ6-AK6 -> 7 | AM6: 0 | AN6: 0 | AO6: =AL6+AM6-AN6 -> 7 | AP6: 0 | AQ6: 1 | AR6: =AO6+AP6-AQ6 -> 6 | AS6: 0 | AT6: 0 | AU6: =AR6+AS6-AT6 -> 6 | AV6: 0 | AW6: 0 | AX6: =AU6+AV6-AW6 -> 6 | AY6: 0 | AZ6: 0 | BA6: =AX6+AY6-AZ6 -> 6 | BB6: 0 | BC6: 0 | BD6: =BA6+BB6-BC6 -> 6 | BE6: 0 | BF6: 1 | BG6: =BD6+BE6-BF6 -> 5 | BH6: 0 | BI6: 0 | BJ6: =BG6+BH6-BI6 -> 5 | BK6: 0 | BL6: 0 | BM6: =BJ6+BK6-BL6 -> 5 | BN6: 0 | BO6: =BM6-BN6 -> 5
A7: GASEOSA CUATRO | B7: 10 | C7: 0 | D7: =B7-C7 -> 10 | E7: 1 | F7: =D7-E7 -> 9 | G7: 1 | H7: =F7-G7 -> 8 | I7: 0 | J7: 1 | K7: =H7+I7-J7 -> 7 | L7: 0 | M7: 0 | N7: =K7+L7-M7 -> 7 | O7: 1 | P7: 0 | Q7: =N7+P7-O7 -> 6 | R7: 0 | S7: 0 | T7: =Q7+S7-R7 -> 6 | U7: 0 | V7: 0 | W7: =T7+V7-U7 -> 6 | X7: 0 | Y7: 0 | Z7: =W7+X7-Y7 -> 6 | AA7: 0 | AB7: 0 | AC7: =Z7+AA7-AB7 -> 6 | AD7: 0 | AE7: 0 | AF7: =AC7+AD7-AE7 -> 6 | AG7: 0 | AH7: 0 | AI7: =AF7+AG7-AH7 -> 6 | AJ7: 0 | AK7: 0 | AL7: =AI7+AJ7-AK7 -> 6 | AM7: 0 | AN7: 0 | AO7: =AL7+AM7-AN7 -> 6 | AP7: 0 | AQ7: 0 | AR7: =AO7+AP7-AQ7 -> 6 | AS7: 0 | AT7: 0 | AU7: =AR7+AS7-AT7 -> 6 | AV7: 0 | AW7: 0 | AX7: =AU7+AV7-AW7 -> 6 | AY7: 0 | AZ7: 0 | BA7: =AX7+AY7-AZ7 -> 6 | BB7: 0 | BC7: 0 | BD7: =BA7+BB7-BC7 -> 6 | BE7: 0 | BF7: 0 | BG7: =BD7+BE7-BF7 -> 6 | BH7: 0 | BI7: 0 | BJ7: =BG7+BH7-BI7 -> 6 | BK7: 0 | BL7: 0 | BM7: =BJ7+BK7-BL7 -> 6 | BN7: 0 | BO7: =BM7-BN7 -> 6
A8: GASEOSA CANADA DRY | B8: 20 | C8: 2 | D8: =B8-C8 -> 18 | E8: 4 | F8: =D8-E8 -> 14 | G8: 0 | H8: =F8-G8 -> 14 | I8: 0 | J8: 0 | K8: =H8+I8-J8 -> 14 | L8: 0 | M8: 0 | N8: =K8+L8-M8 -> 14 | O8: 0 | P8: 0 | Q8: =N8+P8-O8 -> 14 | R8: 1 | S8: 0 | T8: =Q8+S8-R8 -> 13 | U8: 2 | V8: 0 | W8: =T8+V8-U8 -> 11 | X8: 0 | Y8: 1 | Z8: =W8+X8-Y8 -> 10 | AA8: 0 | AB8: 0 | AC8: =Z8+AA8-AB8 -> 10 | AD8: 0 | AE8: 1 | AF8: =AC8+AD8-AE8 -> 9 | AG8: 0 | AH8: 0 | AI8: =AF8+AG8-AH8 -> 9 | AJ8: 0 | AK8: 0 | AL8: =AI8+AJ8-AK8 -> 9 | AM8: 0 | AN8: 1 | AO8: =AL8+AM8-AN8 -> 8 | AP8: 0 | AQ8: 0 | AR8: =AO8+AP8-AQ8 -> 8 | AS8: 0 | AT8: 0 | AU8: =AR8+AS8-AT8 -> 8 | AV8: 0 | AW8: 1 | AX8: =AU8+AV8-AW8 -> 7 | AY8: 0 | AZ8: 0 | BA8: =AX8+AY8-AZ8 -> 7 | BB8: 0 | BC8: 0 | BD8: =BA8+BB8-BC8 -> 7 | BE8: 0 | BF8: 0 | BG8: =BD8+BE8-BF8 -> 7 | BH8: 0 | BI8: 0 | BJ8: =BG8+BH8-BI8 -> 7 | BK8: 0 | BL8: 0 | BM8: =BJ8+BK8-BL8 -> 7 | BN8: 0 | BO8: =BM8-BN8 -> 7
A9: GASEOSA SHWEPPES | B9: 10 | C9: 0 | D9: =B9-C9 -> 10 | E9: 0 | F9: =D9-E9 -> 10 | G9: 0 | H9: =F9-G9 -> 10 | I9: 0 | J9: 0 | K9: =H9+I9-J9 -> 10 | L9: 0 | M9: 0 | N9: =K9+L9-M9 -> 10 | O9: 0 | P9: 0 | Q9: =N9+P9-O9 -> 10 | R9: 0 | S9: 0 | T9: =Q9+S9-R9 -> 10 | U9: 0 | V9: 0 | W9: =T9+V9-U9 -> 10 | X9: 0 | Y9: 0 | Z9: =W9+X9-Y9 -> 10 | AA9: 0 | AB9: 0 | AC9: =Z9+AA9-AB9 -> 10 | AD9: 0 | AE9: 1 | AF9: =AC9+AD9-AE9 -> 9 | AG9: 0 | AH9: 0 | AI9: =AF9+AG9-AH9 -> 9 | AJ9: 0 | AK9: 0 | AL9: =AI9+AJ9-AK9 -> 9 | AM9: 0 | AN9: 0 | AO9: =AL9+AM9-AN9 -> 9 | AP9: 0 | AQ9: 0 | AR9: =AO9+AP9-AQ9 -> 9 | AS9: 0 | AT9: 0 | AU9: =AR9+AS9-AT9 -> 9 | AV9: 0 | AW9: 0 | AX9: =AU9+AV9-AW9 -> 9 | AY9: 0 | AZ9: 0 | BA9: =AX9+AY9-AZ9 -> 9 | BB9: 0 | BC9: 0 | BD9: =BA9+BB9-BC9 -> 9 | BE9: 0 | BF9: 0 | BG9: =BD9+BE9-BF9 -> 9 | BH9: 0 | BI9: 0 | BJ9: =BG9+BH9-BI9 -> 9 | BK9: 0 | BL9: 0 | BM9: =BJ9+BK9-BL9 -> 9 | BN9: 0 | BO9: =BM9-BN9 -> 9
A10: BRETAÑA | B10: 19 | C10: 0 | D10: =B10-C10 -> 19 | E10: 1 | F10: =D10-E10 -> 18 | G10: 0 | H10: =F10-G10 -> 18 | I10: 0 | J10: 1 | K10: =H10+I10-J10 -> 17 | L10: 0 | M10: 0 | N10: =K10+L10-M10 -> 17 | O10: 0 | P10: 0 | Q10: =N10+P10-O10 -> 17 | R10: 0 | S10: 0 | T10: =Q10+S10-R10 -> 17 | U10: 0 | V10: 0 | W10: =T10+V10-U10 -> 17 | X10: 0 | Y10: 0 | Z10: =W10+X10-Y10 -> 17 | AA10: 0 | AB10: 1 | AC10: =Z10+AA10-AB10 -> 16 | AD10: 0 | AE10: 1 | AF10: =AC10+AD10-AE10 -> 15 | AG10: 0 | AH10: 0 | AI10: =AF10+AG10-AH10 -> 15 | AJ10: 0 | AK10: 1 | AL10: =AI10+AJ10-AK10 -> 14 | AM10: 0 | AN10: 0 | AO10: =AL10+AM10-AN10 -> 14 | AP10: 0 | AQ10: 5 | AR10: =AO10+AP10-AQ10 -> 9 | AS10: 0 | AT10: 2 | AU10: =AR10+AS10-AT10 -> 7 | AV10: 0 | AW10: 0 | AX10: =AU10+AV10-AW10 -> 7 | AY10: 0 | AZ10: 1 | BA10: =AX10+AY10-AZ10 -> 6 | BB10: 0 | BC10: 0 | BD10: =BA10+BB10-BC10 -> 6 | BE10: 0 | BF10: 0 | BG10: =BD10+BE10-BF10 -> 6 | BH10: 0 | BI10: 2 | BJ10: =BG10+BH10-BI10 -> 4 | BK10: 0 | BL10: 0 | BM10: =BJ10+BK10-BL10 -> 4 | BN10: 0 | BO10: =BM10-BN10 -> 4
A11: SPEED MAX | B11: 19 | C11: 0 | D11: =B11-C11 -> 19 | E11: 0 | F11: =D11-E11 -> 19 | G11: 0 | H11: =F11-G11 -> 19 | I11: 0 | J11: 0 | K11: =H11+I11-J11 -> 19 | L11: 0 | M11: 0 | N11: =K11+L11-M11 -> 19 | O11: 0 | P11: 0 | Q11: =N11+P11-O11 -> 19 | R11: 0 | S11: 0 | T11: =Q11+S11-R11 -> 19 | U11: 0 | V11: 0 | W11: =T11+V11-U11 -> 19 | X11: 0 | Y11: 0 | Z11: =W11+X11-Y11 -> 19 | AA11: 0 | AB11: 0 | AC11: =Z11+AA11-AB11 -> 19 | AD11: 0 | AE11: 0 | AF11: =AC11+AD11-AE11 -> 19 | AG11: 0 | AH11: 2 | AI11: =AF11+AG11-AH11 -> 17 | AJ11: 0 | AK11: 1 | AL11: =AI11+AJ11-AK11 -> 16 | AM11: 0 | AN11: 0 | AO11: =AL11+AM11-AN11 -> 16 | AP11: 0 | AQ11: 0 | AR11: =AO11+AP11-AQ11 -> 16 | AS11: 0 | AT11: 0 | AU11: =AR11+AS11-AT11 -> 16 | AV11: 0 | AW11: 0 | AX11: =AU11+AV11-AW11 -> 16 | AY11: 0 | AZ11: 0 | BA11: =AX11+AY11-AZ11 -> 16 | BB11: 0 | BC11: 0 | BD11: =BA11+BB11-BC11 -> 16 | BE11: 0 | BF11: 0 | BG11: =BD11+BE11-BF11 -> 16 | BH11: 0 | BI11: 0 | BJ11: =BG11+BH11-BI11 -> 16 | BK11: 0 | BL11: 0 | BM11: =BJ11+BK11-BL11 -> 16 | BN11: 0 | BO11: =BM11-BN11 -> 16
A12: REDBULL | B12: 6 | C12: 0 | D12: =B12-C12 -> 6 | E12: 0 | F12: =D12-E12 -> 6 | G12: 0 | H12: =F12-G12 -> 6 | I12: 0 | J12: 1 | K12: =H12+I12-J12 -> 5 | L12: 0 | M12: 0 | N12: =K12+L12-M12 -> 5 | O12: 0 | P12: 0 | Q12: =N12+P12-O12 -> 5 | R12: 0 | S12: 0 | T12: =Q12+S12-R12 -> 5 | U12: 0 | V12: 0 | W12: =T12+V12-U12 -> 5 | X12: 0 | Y12: 0 | Z12: =W12+X12-Y12 -> 5 | AA12: 0 | AB12: 0 | AC12: =Z12+AA12-AB12 -> 5 | AD12: 0 | AE12: 0 | AF12: =AC12+AD12-AE12 -> 5 | AG12: 0 | AH12: 0 | AI12: =AF12+AG12-AH12 -> 5 | AJ12: 0 | AK12: 0 | AL12: =AI12+AJ12-AK12 -> 5 | AM12: 0 | AN12: 0 | AO12: =AL12+AM12-AN12 -> 5 | AP12: 0 | AQ12: 0 | AR12: =AO12+AP12-AQ12 -> 5 | AS12: 0 | AT12: 0 | AU12: =AR12+AS12-AT12 -> 5 | AV12: 0 | AW12: 0 | AX12: =AU12+AV12-AW12 -> 5 | AY12: 0 | AZ12: 0 | BA12: =AX12+AY12-AZ12 -> 5 | BB12: 0 | BC12: 0 | BD12: =BA12+BB12-BC12 -> 5 | BE12: 0 | BF12: 0 | BG12: =BD12+BE12-BF12 -> 5 | BH12: 0 | BI12: 0 | BJ12: =BG12+BH12-BI12 -> 5 | BK12: 0 | BL12: 0 | BM12: =BJ12+BK12-BL12 -> 5 | BN12: 0 | BO12: =BM12-BN12 -> 5
A13: ELECTROLIT | B13: 13 | C13: 0 | D13: =B13-C13 -> 13 | E13: 0 | F13: =D13-E13 -> 13 | G13: 0 | H13: =F13-G13 -> 13 | I13: 0 | J13: 3 | K13: =H13+I13-J13 -> 10 | L13: 7 | M13: 16 | N13: =K13+L13-M13 -> 1 | O13: 0 | P13: 12 | Q13: =N13+P13-O13 -> 13 | R13: 0 | S13: 0 | T13: =Q13+S13-R13 -> 13 | U13: 0 | V13: 0 | W13: =T13+V13-U13 -> 13 | X13: 0 | Y13: 0 | Z13: =W13+X13-Y13 -> 13 | AA13: 0 | AB13: 0 | AC13: =Z13+AA13-AB13 -> 13 | AD13: 0 | AE13: 0 | AF13: =AC13+AD13-AE13 -> 13 | AG13: 0 | AH13: 1 | AI13: =AF13+AG13-AH13 -> 12 | AJ13: 0 | AK13: 1 | AL13: =AI13+AJ13-AK13 -> 11 | AM13: 0 | AN13: 0 | AO13: =AL13+AM13-AN13 -> 11 | AP13: 0 | AQ13: 0 | AR13: =AO13+AP13-AQ13 -> 11 | AS13: 0 | AT13: 0 | AU13: =AR13+AS13-AT13 -> 11 | AV13: 0 | AW13: 0 | AX13: =AU13+AV13-AW13 -> 11 | AY13: 0 | AZ13: 0 | BA13: =AX13+AY13-AZ13 -> 11 | BB13: 0 | BC13: 0 | BD13: =BA13+BB13-BC13 -> 11 | BE13: 0 | BF13: 0 | BG13: =BD13+BE13-BF13 -> 11 | BH13: 0 | BI13: 1 | BJ13: =BG13+BH13-BI13 -> 10 | BK13: 0 | BL13: 0 | BM13: =BJ13+BK13-BL13 -> 10 | BN13: 0 | BO13: =BM13-BN13 -> 10
A14: POKER LATA | B14: 12 | C14: 0 | D14: =B14-C14 -> 12 | E14: 0 | F14: =D14-E14 -> 12 | G14: 0 | H14: =F14-G14 -> 12 | I14: 0 | J14: 0 | K14: =H14+I14-J14 -> 12 | L14: 0 | M14: 0 | N14: =K14+L14-M14 -> 12 | O14: 1 | P14: 0 | Q14: =N14+P14-O14 -> 11 | R14: 0 | S14: 0 | T14: =Q14+S14-R14 -> 11 | U14: 0 | V14: 0 | W14: =T14+V14-U14 -> 11 | X14: 0 | Y14: 0 | Z14: =W14+X14-Y14 -> 11 | AA14: 0 | AB14: 0 | AC14: =Z14+AA14-AB14 -> 11 | AD14: 0 | AE14: 0 | AF14: =AC14+AD14-AE14 -> 11 | AG14: 0 | AH14: 0 | AI14: =AF14+AG14-AH14 -> 11 | AJ14: 0 | AK14: 0 | AL14: =AI14+AJ14-AK14 -> 11 | AM14: 0 | AN14: 0 | AO14: =AL14+AM14-AN14 -> 11 | AP14: 0 | AQ14: 0 | AR14: =AO14+AP14-AQ14 -> 11 | AS14: 0 | AT14: 0 | AU14: =AR14+AS14-AT14 -> 11 | AV14: 0 | AW14: 0 | AX14: =AU14+AV14-AW14 -> 11 | AY14: 0 | AZ14: 0 | BA14: =AX14+AY14-AZ14 -> 11 | BB14: 0 | BC14: 0 | BD14: =BA14+BB14-BC14 -> 11 | BE14: 0 | BF14: 0 | BG14: =BD14+BE14-BF14 -> 11 | BH14: 0 | BI14: 0 | BJ14: =BG14+BH14-BI14 -> 11 | BK14: 0 | BL14: 0 | BM14: =BJ14+BK14-BL14 -> 11 | BN14: 0 | BO14: =BM14-BN14 -> 11
A15: AGUILA LATA | B15: 4 | C15: 0 | D15: =B15-C15 -> 4 | E15: 0 | F15: =D15-E15 -> 4 | G15: 3 | H15: =F15-G15 -> 1 | I15: 0 | J15: 0 | K15: =H15+I15-J15 -> 1 | L15: 0 | M15: 0 | N15: =K15+L15-M15 -> 1 | O15: 1 | P15: 0 | Q15: =N15+P15-O15 -> 0 | R15: 0 | S15: 0 | T15: =Q15+S15-R15 -> 0 | U15: 0 | V15: 0 | W15: =T15+V15-U15 -> 0 | X15: 0 | Y15: 0 | Z15: =W15+X15-Y15 -> 0 | AA15: 0 | AB15: 0 | AC15: =Z15+AA15-AB15 -> 0 | AD15: 0 | AE15: 0 | AF15: =AC15+AD15-AE15 -> 0 | AG15: 0 | AH15: 0 | AI15: =AF15+AG15-AH15 -> 0 | AJ15: 0 | AK15: 0 | AL15: =AI15+AJ15-AK15 -> 0 | AM15: 0 | AN15: 0 | AO15: =AL15+AM15-AN15 -> 0 | AP15: 0 | AQ15: 0 | AR15: =AO15+AP15-AQ15 -> 0 | AS15: 0 | AT15: 0 | AU15: =AR15+AS15-AT15 -> 0 | AV15: 0 | AW15: 0 | AX15: =AU15+AV15-AW15 -> 0 | AY15: 0 | AZ15: 0 | BA15: =AX15+AY15-AZ15 -> 0 | BB15: 0 | BC15: 0 | BD15: =BA15+BB15-BC15 -> 0 | BE15: 0 | BF15: 0 | BG15: =BD15+BE15-BF15 -> 0 | BH15: 0 | BI15: 0 | BJ15: =BG15+BH15-BI15 -> 0 | BK15: 0 | BL15: 0 | BM15: =BJ15+BK15-BL15 -> 0 | BN15: 0 | BO15: =BM15-BN15 -> 0
A16: CORONITA LATA | B16: 11 | C16: 0 | D16: =B16-C16 -> 11 | E16: 0 | F16: =D16-E16 -> 11 | G16: 0 | H16: =F16-G16 -> 11 | I16: 0 | J16: 0 | K16: =H16+I16-J16 -> 11 | L16: 0 | M16: 0 | N16: =K16+L16-M16 -> 11 | O16: 0 | P16: 0 | Q16: =N16+P16-O16 -> 11 | R16: 0 | S16: 0 | T16: =Q16+S16-R16 -> 11 | U16: 0 | V16: 0 | W16: =T16+V16-U16 -> 11 | X16: 0 | Y16: 0 | Z16: =W16+X16-Y16 -> 11 | AA16: 0 | AB16: 0 | AC16: =Z16+AA16-AB16 -> 11 | AD16: 0 | AE16: 0 | AF16: =AC16+AD16-AE16 -> 11 | AG16: 0 | AH16: 0 | AI16: =AF16+AG16-AH16 -> 11 | AJ16: 0 | AK16: 0 | AL16: =AI16+AJ16-AK16 -> 11 | AM16: 0 | AN16: 0 | AO16: =AL16+AM16-AN16 -> 11 | AP16: 0 | AQ16: 0 | AR16: =AO16+AP16-AQ16 -> 11 | AS16: 0 | AT16: 0 | AU16: =AR16+AS16-AT16 -> 11 | AV16: 0 | AW16: 0 | AX16: =AU16+AV16-AW16 -> 11 | AY16: 0 | AZ16: 0 | BA16: =AX16+AY16-AZ16 -> 11 | BB16: 0 | BC16: 0 | BD16: =BA16+BB16-BC16 -> 11 | BE16: 0 | BF16: 0 | BG16: =BD16+BE16-BF16 -> 11 | BH16: 0 | BI16: 0 | BJ16: =BG16+BH16-BI16 -> 11 | BK16: 0 | BL16: 0 | BM16: =BJ16+BK16-BL16 -> 11 | BN16: 0 | BO16: =BM16-BN16 -> 11
A17: CORONA LATA | B17: 2 | C17: 0 | D17: =B17-C17 -> 2 | E17: 0 | F17: =D17-E17 -> 2 | G17: 0 | H17: =F17-G17 -> 2 | I17: 0 | J17: 0 | K17: =H17+I17-J17 -> 2 | L17: 0 | M17: 0 | N17: =K17+L17-M17 -> 2 | O17: 0 | P17: 0 | Q17: =N17+P17-O17 -> 2 | R17: 0 | S17: 0 | T17: =Q17+S17-R17 -> 2 | U17: 0 | V17: 0 | W17: =T17+V17-U17 -> 2 | X17: 0 | Y17: 0 | Z17: =W17+X17-Y17 -> 2 | AA17: 0 | AB17: 0 | AC17: =Z17+AA17-AB17 -> 2 | AD17: 0 | AE17: 0 | AF17: =AC17+AD17-AE17 -> 2 | AG17: 0 | AH17: 0 | AI17: =AF17+AG17-AH17 -> 2 | AJ17: 0 | AK17: 0 | AL17: =AI17+AJ17-AK17 -> 2 | AM17: 0 | AN17: 0 | AO17: =AL17+AM17-AN17 -> 2 | AP17: 0 | AQ17: 0 | AR17: =AO17+AP17-AQ17 -> 2 | AS17: 0 | AT17: 0 | AU17: =AR17+AS17-AT17 -> 2 | AV17: 0 | AW17: 0 | AX17: =AU17+AV17-AW17 -> 2 | AY17: 0 | AZ17: 0 | BA17: =AX17+AY17-AZ17 -> 2 | BB17: 0 | BC17: 0 | BD17: =BA17+BB17-BC17 -> 2 | BE17: 0 | BF17: 0 | BG17: =BD17+BE17-BF17 -> 2 | BH17: 0 | BI17: 0 | BJ17: =BG17+BH17-BI17 -> 2 | BK17: 0 | BL17: 0 | BM17: =BJ17+BK17-BL17 -> 2 | BN17: 0 | BO17: =BM17-BN17 -> 2
A18: HEINEKEN LATA | B18: 4 | C18: 0 | D18: =B18-C18 -> 4 | E18: 0 | F18: =D18-E18 -> 4 | G18: 0 | H18: =F18-G18 -> 4 | I18: 0 | J18: 0 | K18: =H18+I18-J18 -> 4 | L18: 0 | M18: 0 | N18: =K18+L18-M18 -> 4 | O18: 0 | P18: 0 | Q18: =N18+P18-O18 -> 4 | R18: 0 | S18: 0 | T18: =Q18+S18-R18 -> 4 | U18: 0 | V18: 0 | W18: =T18+V18-U18 -> 4 | X18: 0 | Y18: 0 | Z18: =W18+X18-Y18 -> 4 | AA18: 0 | AB18: 0 | AC18: =Z18+AA18-AB18 -> 4 | AD18: 0 | AE18: 0 | AF18: =AC18+AD18-AE18 -> 4 | AG18: 0 | AH18: 0 | AI18: =AF18+AG18-AH18 -> 4 | AJ18: 0 | AK18: 0 | AL18: =AI18+AJ18-AK18 -> 4 | AM18: 0 | AN18: 0 | AO18: =AL18+AM18-AN18 -> 4 | AP18: 0 | AQ18: 0 | AR18: =AO18+AP18-AQ18 -> 4 | AS18: 0 | AT18: 0 | AU18: =AR18+AS18-AT18 -> 4 | AV18: 0 | AW18: 0 | AX18: =AU18+AV18-AW18 -> 4 | AY18: 0 | AZ18: 0 | BA18: =AX18+AY18-AZ18 -> 4 | BB18: 0 | BC18: 0 | BD18: =BA18+BB18-BC18 -> 4 | BE18: 0 | BF18: 0 | BG18: =BD18+BE18-BF18 -> 4 | BH18: 0 | BI18: 0 | BJ18: =BG18+BH18-BI18 -> 4 | BK18: 0 | BL18: 0 | BM18: =BJ18+BK18-BL18 -> 4 | BN18: 0 | BO18: =BM18-BN18 -> 4
... A24: HEINEKEN BOTELLA | B24: 25 | C24: 5 | D24: =B24-C24 -> 20 | E24: 0 | F24: =D24-E24 -> 20 | G24: 0 | H24: =F24-G24 -> 20 | I24: 0 | J24: 0 | K24: =H24+I24-J24 -> 20 | L24: 0 | M24: 0 | N24: =K24+L24-M24 -> 20 | O24: 0 | P24: 0 | Q24: =N24+P24-O24 -> 20 | R24: 0 | S24: 0 | T24: =Q24+S24-R24 -> 20 | U24: 0 | V24: 0 | W24: =T24+V24-U24 -> 20 | X24: 0 | Y24: 0 | Z24: =W24+X24-Y24 -> 20 | AA24: 0 | AB24: 0 | AC24: =Z24+AA24-AB24 -> 20 | AD24: 0 | AE24: 0 | AF24: =AC24+AD24-AE24 -> 20 | AG24: 0 | AH24: 0 | AI24: =AF24+AG24-AH24 -> 20 | AJ24: 0 | AK24: 0 | AL24: =AI24+AJ24-AK24 -> 20 | AM24: 0 | AN24: 0 | AO24: =AL24+AM24-AN24 -> 20 | AP24: 0 | AQ24: 0 | AR24: =AO24+AP24-AQ24 -> 20 | AS24: 0 | AT24: 4 | AU24: =AR24+AS24-AT24 -> 16 | AV24: 0 | AW24: 0 | AX24: =AU24+AV24-AW24 -> 16 | AY24: 0 | AZ24: 0 | BA24: =AX24+AY24-AZ24 -> 16 | BB24: 0 | BC24: 0 | BD24: =BA24+BB24-BC24 -> 16 | BE24: 0 | BF24: 0 | BG24: =BD24+BE24-BF24 -> 16 | BH24: 0 | BI24: 0 | BJ24: =BG24+BH24-BI24 -> 16 | BK24: 0 | BL24: 0 | BM24: =BJ24+BK24-BL24 -> 16 | BN24: 0 | BO24: =BM24-BN24 -> 16
A25: CORONITA | B25: 44 | C25: 0 | D25: =B25-C25 -> 44 | E25: 0 | F25: =D25-E25 -> 44 | G25: 19 | H25: =F25-G25 -> 25 | I25: 0 | J25: 14 | K25: =H25+I25-J25 -> 11 | L25: 12 | M25: 10 | N25: =K25+L25-M25 -> 13 | O25: 0 | P25: 36 | Q25: =N25+P25-O25 -> 49 | R25: 0 | S25: 0 | T25: 48 | U25: 1 | V25: 0 | W25: =T25+V25-U25 -> 47 | X25: 0 | Y25: 18 | Z25: =W25+X25-Y25 -> 29 | AA25: 24 | AB25: 12 | AC25: =Z25+AA25-AB25 -> 41 | AD25: 0 | AE25: 10 | AF25: =AC25+AD25-AE25 -> 31 | AG25: 0 | AH25: 10 | AI25: =AF25+AG25-AH25 -> 21 | AJ25: 0 | AK25: 16 | AL25: =AI25+AJ25-AK25 -> 5 | AM25: 48 | AN25: 0 | AO25: =AL25+AM25-AN25 -> 53 | AP25: 0 | AQ25: 12 | AR25: =AO25+AP25-AQ25 -> 41 | AS25: 0 | AT25: 0 | AU25: =AR25+AS25-AT25 -> 41 | AV25: 66 | AW25: 103 | AX25: =AU25+AV25-AW25 -> 4 | AY25: 54 | AZ25: 0 | BA25: =AX25+AY25-AZ25 -> 58 | BB25: 0 | BC25: 21 | BD25: =BA25+BB25-BC25 -> 37 | BE25: 0 | BF25: 0 | BG25: =BD25+BE25-BF25 -> 37 | BH25: 0 | BI25: 0 | BJ25: =BG25+BH25-BI25 -> 37 | BK25: 0 | BL25: 0 | BM25: =BJ25+BK25-BL25 -> 37 | BN25: 11 | BO25: =BM25-BN25 -> 26
A26: AGUILA | B26: 186 | C26: 14 | D26: =B26-C26 -> 172 | E26: 58 | F26: =D26-E26 -> 114 | G26: 56 | H26: =F26-G26 -> 58 | I26: 120 | J26: 24 | K26: =H26+I26-J26 -> 154 | L26: 0 | M26: 67 | N26: =K26+L26-M26 -> 87 | O26: 22 | P26: 90 | Q26: =N26+P26-O26 -> 155 | R26: 26 | S26: 0 | T26: =Q26+S26-R26 -> 129 | U26: 40 | V26: 60 | W26: =T26+V26-U26 -> 149 | X26: 30 | Y26: 48 | Z26: =W26+X26-Y26 -> 131 | AA26: 60 | AB26: 90 | AC26: =Z26+AA26-AB26 -> 101 | AD26: 90 | AE26: 55 | AF26: =AC26+AD26-AE26 -> 136 | AG26: 45 | AH26: 19 | AI26: 163 | AJ26: 0 | AK26: 18 | AL26: =AI26+AJ26-AK26 -> 145 | AM26: 0 | AN26: 27 | AO26: =AL26+AM26-AN26 -> 118 | AP26: 120 | AQ26: 93 | AR26: =AO26+AP26-AQ26 -> 145 | AS26: 30 | AT26: 64 | AU26: =AR26+AS26-AT26 -> 111 | AV26: 60 | AW26: 65 | AX26: =AU26+AV26-AW26 -> 106 | AY26: 60 | AZ26: 50 | BA26: =AX26+AY26-AZ26 -> 116 | BB26: 0 | BC26: 39 | BD26: =BA26+BB26-BC26 -> 77 | BE26: 105 | BF26: 38 | BG26: =BD26+BE26-BF26 -> 144 | BH26: 0 | BI26: 47 | BJ26: =BG26+BH26-BI26 -> 97 | BK26: 60 | BL26: 1 | BM26: =BJ26+BK26-BL26 -> 156 | BN26: 15 | BO26: =BM26-BN26 -> 141
A27: LIGTH | B27: 178 | C27: 18 | D27: =B27-C27 -> 160 | E27: 47 | F27: =D27-E27 -> 113 | G27: 14 | H27: 98 | I27: 60 | J27: 55 | K27: =H27+I27-J27 -> 103 | L27: 0 | M27: 27 | N27: =K27+L27-M27 -> 76 | O27: 45 | P27: 90 | Q27: =N27+P27-O27 -> 121 | R27: 13 | S27: 0 | T27: =Q27+S27-R27 -> 108 | U27: 41 | V27: 60 | W27: =T27+V27-U27 -> 127 | X27: 60 | Y27: 25 | Z27: =W27+X27-Y27 -> 162 | AA27: 15 | AB27: 82 | AC27: =Z27+AA27-AB27 -> 95 | AD27: 75 | AE27: 61 | AF27: =AC27+AD27-AE27 -> 109 | AG27: 60 | AH27: 5 | AI27: =AF27+AG27-AH27 -> 164 | AJ27: 0 | AK27: 4 | AL27: =AI27+AJ27-AK27 -> 160 | AM27: 0 | AN27: 14 | AO27: =AL27+AM27-AN27 -> 146 | AP27: 0 | AQ27: 22 | AR27: =AO27+AP27-AQ27 -> 124 | AS27: 60 | AT27: 49 | AU27: =AR27+AS27-AT27 -> 135 | AV27: 60 | AW27: 32 | AX27: =AU27+AV27-AW27 -> 163 | AY27: 60 | AZ27: 74 | BA27: =AX27+AY27-AZ27 -> 149 | BB27: 0 | BC27: 34 | BD27: =BA27+BB27-BC27 -> 115 | BE27: 76 | BF27: 15 | BG27: =BD27+BE27-BF27 -> 176 | BH27: 0 | BI27: 10 | BJ27: =BG27+BH27-BI27 -> 166 | BK27: 0 | BL27: 1 | BM27: =BJ27+BK27-BL27 -> 165 | BN27: 59 | BO27: =BM27-BN27 -> 106
A28: POKER | B28: 83 | C28: 3 | D28: =B28-C28 -> 80 | E28: 0 | F28: =D28-E28 -> 80 | G28: 1 | H28: =F28-G28 -> 79 | I28: 0 | J28: 7 | K28: =H28+I28-J28 -> 72 | L28: 0 | M28: 8 | N28: =K28+L28-M28 -> 64 | O28: 35 | P28: 15 | Q28: =N28+P28-O28 -> 44 | R28: 3 | S28: 0 | T28: 40 | U28: 0 | V28: 0 | W28: =T28+V28-U28 -> 40 | X28: 0 | Y28: 2 | Z28: =W28+X28-Y28 -> 38 | AA28: 0 | AB28: 31 | AC28: =Z28+AA28-AB28 -> 7 | AD28: 75 | AE28: 12 | AF28: =AC28+AD28-AE28 -> 70 | AG28: 0 | AH28: 1 | AI28: =AF28+AG28-AH28 -> 69 | AJ28: 0 | AK28: 13 | AL28: =AI28+AJ28-AK28 -> 56 | AM28: 0 | AN28: 13 | AO28: =AL28+AM28-AN28 -> 43 | AP28: 0 | AQ28: 0 | AR28: =AO28+AP28-AQ28 -> 43 | AS28: 0 | AT28: 0 | AU28: =AR28+AS28-AT28 -> 43 | AV28: 30 | AW28: 6 | AX28: =AU28+AV28-AW28 -> 67 | AY28: 0 | AZ28: 18 | BA28: =AX28+AY28-AZ28 -> 49 | BB28: 0 | BC28: 2 | BD28: =BA28+BB28-BC28 -> 47 | BE28: 30 | BF28: 5 | BG28: =BD28+BE28-BF28 -> 72 | BH28: 0 | BI28: 6 | BJ28: =BG28+BH28-BI28 -> 66 | BK28: 0 | BL28: 2 | BM28: =BJ28+BK28-BL28 -> 64 | BN28: 10 | BO28: =BM28-BN28 -> 54
A29: COSTEÑA | B29: 101 | C29: 0 | D29: =B29-C29 -> 101 | E29: 18 | F29: =D29-E29 -> 83 | G29: 7 | H29: =F29-G29 -> 76 | I29: 0 | J29: 25 | K29: 48 | L29: 0 | M29: 0 | N29: 48 | O29: 0 | P29: 45 | Q29: =N29+P29-O29 -> 93 | R29: 4 | S29: 0 | T29: =Q29+S29-R29 -> 89 | U29: 22 | V29: 0 | W29: =T29+V29-U29 -> 67 | X29: 30 | Y29: 15 | Z29: =W29+X29-Y29 -> 82 | AA29: 15 | AB29: 12 | AC29: =Z29+AA29-AB29 -> 85 | AD29: 15 | AE29: 43 | AF29: =AC29+AD29-AE29 -> 57 | AG29: 30 | AH29: 0 | AI29: =AF29+AG29-AH29 -> 87 | AJ29: 0 | AK29: 3 | AL29: =AI29+AJ29-AK29 -> 84 | AM29: 0 | AN29: 0 | AO29: =AL29+AM29-AN29 -> 84 | AP29: 0 | AQ29: 1 | AR29: =AO29+AP29-AQ29 -> 83 | AS29: 0 | AT29: 1 | AU29: =AR29+AS29-AT29 -> 82 | AV29: 0 | AW29: 0 | AX29: =AU29+AV29-AW29 -> 82 | AY29: 0 | AZ29: 22 | BA29: =AX29+AY29-AZ29 -> 60 | BB29: 0 | BC29: 0 | BD29: =BA29+BB29-BC29 -> 60 | BE29: 30 | BF29: 4 | BG29: =BD29+BE29-BF29 -> 86 | BH29: 0 | BI29: 6 | BJ29: =BG29+BH29-BI29 -> 80 | BK29: 0 | BL29: 4 | BM29: =BJ29+BK29-BL29 -> 76 | BN29: 0 | BO29: =BM29-BN29 -> 76
A30: CLUB | B30: 70 | C30: 5 | D30: =B30-C30 -> 65 | E30: 1 | F30: =D30-E30 -> 64 | G30: 12 | H30: =F30-G30 -> 52 | I30: 0 | J30: 0 | K30: =H30+I30-J30 -> 52 | L30: 0 | M30: 0 | N30: =K30+L30-M30 -> 52 | O30: 0 | P30: 15 | Q30: =N30+P30-O30 -> 67 | R30: 0 | S30: 0 | T30: =Q30+S30-R30 -> 67 | U30: 0 | V30: 0 | W30: =T30+V30-U30 -> 67 | X30: 0 | Y30: 12 | Z30: =W30+X30-Y30 -> 55 | AA30: 15 | AB30: 0 | AC30: =Z30+AA30-AB30 -> 70 | AD30: 0 | AE30: 18 | AF30: =AC30+AD30-AE30 -> 52 | AG30: 15 | AH30: 0 | AI30: =AF30+AG30-AH30 -> 67 | AJ30: 0 | AK30: 11 | AL30: =AI30+AJ30-AK30 -> 56 | AM30: 0 | AN30: 0 | AO30: =AL30+AM30-AN30 -> 56 | AP30: 0 | AQ30: 3 | AR30: =AO30+AP30-AQ30 -> 53 | AS30: 15 | AT30: 0 | AU30: =AR30+AS30-AT30 -> 68 | AV30: 0 | AW30: 25 | AX30: =AU30+AV30-AW30 -> 43 | AY30: 0 | AZ30: 8 | BA30: =AX30+AY30-AZ30 -> 35 | BB30: 0 | BC30: 5 | BD30: =BA30+BB30-BC30 -> 30 | BE30: 30 | BF30: 1 | BG30: =BD30+BE30-BF30 -> 59 | BH30: 0 | BI30: 6 | BJ30: =BG30+BH30-BI30 -> 53 | BK30: 0 | BL30: 0 | BM30: =BJ30+BK30-BL30 -> 53 | BN30: 0 | BO30: =BM30-BN30 -> 53
A31: 1/2 AG. ANTIOQUEÑO VERDE | B31: 5 | C31: 0 | D31: =B31-C31 -> 5 | E31: 1 | F31: =D31-E31 -> 4 | G31: 0 | H31: =F31-G31 -> 4 | I31: 9 | J31: 12 | K31: =H31+I31-J31 -> 1 | L31: 11 | M31: 11 | N31: =K31+L31-M31 -> 1 | O31: 0 | P31: 4 | Q31: =N31+P31-O31 -> 5 | R31: 0 | S31: 0 | T31: =Q31+S31-R31 -> 5 | U31: 0 | V31: 0 | W31: =T31+V31-U31 -> 5 | X31: 0 | Y31: 0 | Z31: =W31+X31-Y31 -> 5 | AA31: 0 | AB31: 0 | AC31: =Z31+AA31-AB31 -> 5 | AD31: 0 | AE31: 1 | AF31: =AC31+AD31-AE31 -> 4 | AG31: 1 | AH31: 2 | AI31: =AF31+AG31-AH31 -> 3 | AJ31: 3 | AK31: 6 | AL31: =AI31+AJ31-AK31 -> 0 | AM31: 5 | AN31: 0 | AO31: =AL31+AM31-AN31 -> 5 | AP31: 0 | AQ31: 0 | AR31: =AO31+AP31-AQ31 -> 5 | AS31: 0 | AT31: 0 | AU31: =AR31+AS31-AT31 -> 5 | AV31: 0 | AW31: 1 | AX31: =AU31+AV31-AW31 -> 4 | AY31: 0 | AZ31: 1 | BA31: =AX31+AY31-AZ31 -> 3 | BB31: 2 | BC31: 0 | BD31: =BA31+BB31-BC31 -> 5 | BE31: 0 | BF31: 0 | BG31: =BD31+BE31-BF31 -> 5 | BH31: 0 | BI31: 0 | BJ31: =BG31+BH31-BI31 -> 5 | BK31: 0 | BL31: 0 | BM31: =BJ31+BK31-BL31 -> 5 | BN31: 1 | BO31: =BM31-BN31 -> 4
A32: 1 BOTELLA AG. ANTIOQUEÑO VERDE | B32: 0 | C32: 0 | D32: =B32-C32 -> 0 | E32: 0 | F32: =D32-E32 -> 0 | G32: 0 | H32: =F32-G32 -> 0 | I32: 1 | J32: 1 | K32: =H32+I32-J32 -> 0 | L32: 9 | M32: 9 | N32: =K32+L32-M32 -> 0 | O32: 0 | P32: 0 | Q32: =N32+P32-O32 -> 0 | R32: 0 | S32: 0 | T32: =Q32+S32-R32 -> 0 | U32: 0 | V32: 0 | W32: =T32+V32-U32 -> 0 | X32: 0 | Y32: 0 | Z32: =W32+X32-Y32 -> 0 | AA32: 0 | AB32: 0 | AC32: =Z32+AA32-AB32 -> 0 | AD32: 0 | AE32: 0 | AF32: =AC32+AD32-AE32 -> 0 | AG32: 0 | AH32: 0 | AI32: =AF32+AG32-AH32 -> 0 | AJ32: 1 | AK32: 1 | AL32: =AI32+AJ32-AK32 -> 0 | AM32: 0 | AN32: 0 | AO32: =AL32+AM32-AN32 -> 0 | AP32: 0 | AQ32: 0 | AR32: =AO32+AP32-AQ32 -> 0 | AS32: 0 | AT32: 0 | AU32: =AR32+AS32-AT32 -> 0 | AV32: 0 | AW32: 0 | AX32: =AU32+AV32-AW32 -> 0 | AY32: 0 | AZ32: 0 | BA32: =AX32+AY32-AZ32 -> 0 | BB32: 0 | BC32: 0 | BD32: =BA32+BB32-BC32 -> 0 | BE32: 0 | BF32: 0 | BG32: =BD32+BE32-BF32 -> 0 | BH32: 0 | BI32: 0 | BJ32: =BG32+BH32-BI32 -> 0 | BK32: 0 | BL32: 0 | BM32: =BJ32+BK32-BL32 -> 0 | BN32: 0 | BO32: =BM32-BN32 -> 0
A33: 1/2 AG. ANTIOQUEÑO AZUL | B33: 0 | C33: 0 | D33: =B33-C33 -> 0 | E33: 0 | F33: =D33-E33 -> 0 | G33: 0 | H33: =F33-G33 -> 0 | I33: 0 | J33: 0 | K33: =H33+I33-J33 -> 0 | L33: 0 | M33: 0 | N33: =K33+L33-M33 -> 0 | O33: 0 | P33: 0 | Q33: =N33+P33-O33 -> 0 | R33: 0 | S33: 0 | T33: =Q33+S33-R33 -> 0 | U33: 0 | V33: 0 | W33: =T33+V33-U33 -> 0 | X33: 0 | Y33: 0 | Z33: =W33+X33-Y33 -> 0 | AA33: 0 | AB33: 0 | AC33: =Z33+AA33-AB33 -> 0 | AD33: 0 | AE33: 0 | AF33: =AC33+AD33-AE33 -> 0 | AG33: 0 | AH33: 0 | AI33: =AF33+AG33-AH33 -> 0 | AJ33: 0 | AK33: 0 | AL33: =AI33+AJ33-AK33 -> 0 | AM33: 0 | AN33: 0 | AO33: =AL33+AM33-AN33 -> 0 | AP33: 0 | AQ33: 0 | AR33: =AO33+AP33-AQ33 -> 0 | AS33: 0 | AT33: 0 | AU33: =AR33+AS33-AT33 -> 0 | AV33: 0 | AW33: 0 | AX33: =AU33+AV33-AW33 -> 0 | AY33: 0 | AZ33: 0 | BA33: =AX33+AY33-AZ33 -> 0 | BB33: 0 | BC33: 0 | BD33: =BA33+BB33-BC33 -> 0 | BE33: 0 | BF33: 0 | BG33: =BD33+BE33-BF33 -> 0 | BH33: 0 | BI33: 0 | BJ33: =BG33+BH33-BI33 -> 0 | BK33: 0 | BL33: 0 | BM33: =BJ33+BK33-BL33 -> 0 | BN33: 0 | BO33: =BM33-BN33 -> 0
A34: 1 BOTELLA AG. ANTIOQUEÑO AZUL | B34: 0 | C34: 0 | D34: =B34-C34 -> 0 | E34: 0 | F34: =D34-E34 -> 0 | G34: 0 | H34: =F34-G34 -> 0 | I34: 0 | J34: 0 | K34: =H34+I34-J34 -> 0 | L34: 0 | M34: 0 | N34: =K34+L34-M34 -> 0 | O34: 0 | P34: 0 | Q34: =N34+P34-O34 -> 0 | R34: 0 | S34: 0 | T34: =Q34+S34-R34 -> 0 | U34: 0 | V34: 0 | W34: =T34+V34-U34 -> 0 | X34: 0 | Y34: 0 | Z34: =W34+X34-Y34 -> 0 | AA34: 0 | AB34: 0 | AC34: =Z34+AA34-AB34 -> 0 | AD34: 0 | AE34: 0 | AF34: =AC34+AD34-AE34 -> 0 | AG34: 0 | AH34: 0 | AI34: =AF34+AG34-AH34 -> 0 | AJ34: 0 | AK34: 0 | AL34: =AI34+AJ34-AK34 -> 0 | AM34: 0 | AN34: 0 | AO34: =AL34+AM34-AN34 -> 0 | AP34: 0 | AQ34: 0 | AR34: =AO34+AP34-AQ34 -> 0 | AS34: 0 | AT34: 0 | AU34: =AR34+AS34-AT34 -> 0 | AV34: 0 | AW34: 0 | AX34: =AU34+AV34-AW34 -> 0 | AY34: 0 | AZ34: 0 | BA34: =AX34+AY34-AZ34 -> 0 | BB34: 0 | BC34: 0 | BD34: =BA34+BB34-BC34 -> 0 | BE34: 0 | BF34: 0 | BG34: =BD34+BE34-BF34 -> 0 | BH34: 0 | BI34: 0 | BJ34: =BG34+BH34-BI34 -> 0 | BK34: 0 | BL34: 0 | BM34: =BJ34+BK34-BL34 -> 0 | BN34: 0 | BO34: =BM34-BN34 -> 0
A35: SMIRNOFF LULO PEQUEÑA | B35: 2 | C35: 0 | D35: =B35-C35 -> 2 | E35: 0 | F35: =D35-E35 -> 2 | G35: 0 | H35: =F35-G35 -> 2 | I35: 0 | J35: 0 | K35: =H35+I35-J35 -> 2 | L35: 0 | M35: 0 | N35: =K35+L35-M35 -> 2 | O35: 0 | P35: 0 | Q35: =N35+P35-O35 -> 2 | R35: 0 | S35: 0 | T35: =Q35+S35-R35 -> 2 | U35: 0 | V35: 0 | W35: =T35+V35-U35 -> 2 | X35: 0 | Y35: 0 | Z35: =W35+X35-Y35 -> 2 | AA35: 0 | AB35: 0 | AC35: =Z35+AA35-AB35 -> 2 | AD35: 0 | AE35: 0 | AF35: =AC35+AD35-AE35 -> 2 | AG35: 0 | AH35: 0 | AI35: =AF35+AG35-AH35 -> 2 | AJ35: 0 | AK35: 0 | AL35: =AI35+AJ35-AK35 -> 2 | AM35: 0 | AN35: 0 | AO35: =AL35+AM35-AN35 -> 2 | AP35: 0 | AQ35: 0 | AR35: =AO35+AP35-AQ35 -> 2 | AS35: 0 | AT35: 0 | AU35: =AR35+AS35-AT35 -> 2 | AV35: 0 | AW35: 0 | AX35: =AU35+AV35-AW35 -> 2 | AY35: 0 | AZ35: 0 | BA35: =AX35+AY35-AZ35 -> 2 | BB35: 0 | BC35: 0 | BD35: =BA35+BB35-BC35 -> 2 | BE35: 0 | BF35: 0 | BG35: =BD35+BE35-BF35 -> 2 | BH35: 0 | BI35: 0 | BJ35: =BG35+BH35-BI35 -> 2 | BK35: 0 | BL35: 0 | BM35: =BJ35+BK35-BL35 -> 2 | BN35: 0 | BO35: =BM35-BN35 -> 2
A36: RON MEDELLIN DORADO GRANDE | B36: 1 | C36: 0 | D36: =B36-C36 -> 1 | E36: 0 | F36: =D36-E36 -> 1 | G36: 0 | H36: =F36-G36 -> 1 | I36: 0 | J36: 0 | K36: =H36+I36-J36 -> 1 | L36: 0 | M36: 0 | N36: =K36+L36-M36 -> 1 | O36: 0 | P36: 0 | Q36: =N36+P36-O36 -> 1 | R36: 0 | S36: 0 | T36: =Q36+S36-R36 -> 1 | U36: 0 | V36: 0 | W36: =T36+V36-U36 -> 1 | X36: 0 | Y36: 0 | Z36: =W36+X36-Y36 -> 1 | AA36: 0 | AB36: 0 | AC36: =Z36+AA36-AB36 -> 1 | AD36: 0 | AE36: 0 | AF36: =AC36+AD36-AE36 -> 1 | AG36: 0 | AH36: 0 | AI36: =AF36+AG36-AH36 -> 1 | AJ36: 0 | AK36: 0 | AL36: =AI36+AJ36-AK36 -> 1 | AM36: 0 | AN36: 0 | AO36: =AL36+AM36-AN36 -> 1 | AP36: 0 | AQ36: 0 | AR36: =AO36+AP36-AQ36 -> 1 | AS36: 0 | AT36: 0 | AU36: =AR36+AS36-AT36 -> 1 | AV36: 0 | AW36: 0 | AX36: =AU36+AV36-AW36 -> 1 | AY36: 0 | AZ36: 0 | BA36: =AX36+AY36-AZ36 -> 1 | BB36: 0 | BC36: 0 | BD36: =BA36+BB36-BC36 -> 1 | BE36: 0 | BF36: 0 | BG36: =BD36+BE36-BF36 -> 1 | BH36: 0 | BI36: 0 | BJ36: =BG36+BH36-BI36 -> 1 | BK36: 0 | BL36: 0 | BM36: =BJ36+BK36-BL36 -> 1 | BN36: 0 | BO36: =BM36-BN36 -> 1
A37: RON MEDELLIN DORADO PEQUEÑA | B37: 1 | C37: 0 | D37: =B37-C37 -> 1 | E37: 0 | F37: =D37-E37 -> 1 | G37: 0 | H37: =F37-G37 -> 1 | I37: 0 | J37: 0 | K37: =H37+I37-J37 -> 1 | L37: 0 | M37: 0 | N37: =K37+L37-M37 -> 1 | O37: 0 | P37: 0 | Q37: =N37+P37-O37 -> 1 | R37: 0 | S37: 0 | T37: =Q37+S37-R37 -> 1 | U37: 0 | V37: 0 | W37: =T37+V37-U37 -> 1 | X37: 0 | Y37: 0 | Z37: =W37+X37-Y37 -> 1 | AA37: 0 | AB37: 0 | AC37: =Z37+AA37-AB37 -> 1 | AD37: 0 | AE37: 0 | AF37: =AC37+AD37-AE37 -> 1 | AG37: 0 | AH37: 0 | AI37: =AF37+AG37-AH37 -> 1 | AJ37: 0 | AK37: 0 | AL37: =AI37+AJ37-AK37 -> 1 | AM37: 0 | AN37: 0 | AO37: =AL37+AM37-AN37 -> 1 | AP37: 0 | AQ37: 0 | AR37: =AO37+AP37-AQ37 -> 1 | AS37: 0 | AT37: 0 | AU37: =AR37+AS37-AT37 -> 1 | AV37: 0 | AW37: 0 | AX37: =AU37+AV37-AW37 -> 1 | AY37: 0 | AZ37: 0 | BA37: =AX37+AY37-AZ37 -> 1 | BB37: 0 | BC37: 0 | BD37: =BA37+BB37-BC37 -> 1 | BE37: 0 | BF37: 0 | BG37: =BD37+BE37-BF37 -> 1 | BH37: 0 | BI37: 0 | BJ37: =BG37+BH37-BI37 -> 1 | BK37: 0 | BL37: 0 | BM37: =BJ37+BK37-BL37 -> 1 | BN37: 0 | BO37: =BM37-BN37 -> 1
A38: SOMETHING SPECIAL PEQUEÑA | B38: 1 | C38: 0 | D38: =B38-C38 -> 1 | E38: 0 | F38: =D38-E38 -> 1 | G38: 0 | H38: =F38-G38 -> 1 | I38: 0 | J38: 0 | K38: =H38+I38-J38 -> 1 | L38: 0 | M38: 0 | N38: =K38+L38-M38 -> 1 | O38: 0 | P38: 0 | Q38: =N38+P38-O38 -> 1 | R38: 0 | S38: 0 | T38: =Q38+S38-R38 -> 1 | U38: 0 | V38: 0 | W38: =T38+V38-U38 -> 1 | X38: 0 | Y38: 0 | Z38: =W38+X38-Y38 -> 1 | AA38: 0 | AB38: 0 | AC38: =Z38+AA38-AB38 -> 1 | AD38: 0 | AE38: 0 | AF38: =AC38+AD38-AE38 -> 1 | AG38: 0 | AH38: 0 | AI38: =AF38+AG38-AH38 -> 1 | AJ38: 0 | AK38: 0 | AL38: =AI38+AJ38-AK38 -> 1 | AM38: 0 | AN38: 0 | AO38: =AL38+AM38-AN38 -> 1 | AP38: 0 | AQ38: 0 | AR38: =AO38+AP38-AQ38 -> 1 | AS38: 0 | AT38: 0 | AU38: =AR38+AS38-AT38 -> 1 | AV38: 0 | AW38: 0 | AX38: =AU38+AV38-AW38 -> 1 | AY38: 0 | AZ38: 0 | BA38: =AX38+AY38-AZ38 -> 1 | BB38: 0 | BC38: 0 | BD38: =BA38+BB38-BC38 -> 1 | BE38: 0 | BF38: 0 | BG38: =BD38+BE38-BF38 -> 1 | BH38: 0 | BI38: 0 | BJ38: =BG38+BH38-BI38 -> 1 | BK38: 0 | BL38: 0 | BM38: =BJ38+BK38-BL38 -> 1 | BN38: 0 | BO38: =BM38-BN38 -> 1
A39: BLACK LABEL | B39: 1 | C39: 0 | D39: =B39-C39 -> 1 | E39: 0 | F39: =D39-E39 -> 1 | G39: 0 | H39: =F39-G39 -> 1 | I39: 0 | J39: 0 | K39: =H39+I39-J39 -> 1 | L39: 0 | M39: 0 | N39: =K39+L39-M39 -> 1 | O39: 0 | P39: 0 | Q39: =N39+P39-O39 -> 1 | R39: 0 | S39: 0 | T39: =Q39+S39-R39 -> 1 | U39: 0 | V39: 0 | W39: =T39+V39-U39 -> 1 | X39: 0 | Y39: 0 | Z39: =W39+X39-Y39 -> 1 | AA39: 0 | AB39: 0 | AC39: =Z39+AA39-AB39 -> 1 | AD39: 0 | AE39: 0 | AF39: =AC39+AD39-AE39 -> 1 | AG39: 0 | AH39: 0 | AI39: =AF39+AG39-AH39 -> 1 | AJ39: 0 | AK39: 0 | AL39: =AI39+AJ39-AK39 -> 1 | AM39: 0 | AN39: 0 | AO39: =AL39+AM39-AN39 -> 1 | AP39: 0 | AQ39: 0 | AR39: =AO39+AP39-AQ39 -> 1 | AS39: 0 | AT39: 0 | AU39: =AR39+AS39-AT39 -> 1 | AV39: 0 | AW39: 0 | AX39: =AU39+AV39-AW39 -> 1 | AY39: 0 | AZ39: 0 | BA39: =AX39+AY39-AZ39 -> 1 | BB39: 0 | BC39: 0 | BD39: =BA39+BB39-BC39 -> 1 | BE39: 0 | BF39: 0 | BG39: =BD39+BE39-BF39 -> 1 | BH39: 0 | BI39: 0 | BJ39: =BG39+BH39-BI39 -> 1 | BK39: 0 | BL39: 0 | BM39: =BJ39+BK39-BL39 -> 1 | BN39: 0 | BO39: =BM39-BN39 -> 1
A40: RED LABEL | B40: 1 | C40: 0 | D40: =B40-C40 -> 1 | E40: 0 | F40: =D40-E40 -> 1 | G40: 0 | H40: =F40-G40 -> 1 | I40: 0 | J40: 0 | K40: =H40+I40-J40 -> 1 | L40: 0 | M40: 0 | N40: =K40+L40-M40 -> 1 | O40: 0 | P40: 0 | Q40: =N40+P40-O40 -> 1 | R40: 0 | S40: 0 | T40: =Q40+S40-R40 -> 1 | U40: 0 | V40: 0 | W40: =T40+V40-U40 -> 1 | X40: 0 | Y40: 0 | Z40: =W40+X40-Y40 -> 1 | AA40: 0 | AB40: 0 | AC40: =Z40+AA40-AB40 -> 1 | AD40: 0 | AE40: 0 | AF40: =AC40+AD40-AE40 -> 1 | AG40: 0 | AH40: 0 | AI40: =AF40+AG40-AH40 -> 1 | AJ40: 0 | AK40: 0 | AL40: =AI40+AJ40-AK40 -> 1 | AM40: 0 | AN40: 0 | AO40: =AL40+AM40-AN40 -> 1 | AP40: 0 | AQ40: 0 | AR40: =AO40+AP40-AQ40 -> 1 | AS40: 0 | AT40: 0 | AU40: =AR40+AS40-AT40 -> 1 | AV40: 0 | AW40: 0 | AX40: =AU40+AV40-AW40 -> 1 | AY40: 0 | AZ40: 0 | BA40: =AX40+AY40-AZ40 -> 1 | BB40: 0 | BC40: 0 | BD40: =BA40+BB40-BC40 -> 1 | BE40: 0 | BF40: 0 | BG40: =BD40+BE40-BF40 -> 1 | BH40: 0 | BI40: 0 | BJ40: =BG40+BH40-BI40 -> 1 | BK40: 0 | BL40: 0 | BM40: =BJ40+BK40-BL40 -> 1 | BN40: 0 | BO40: =BM40-BN40 -> 1
A41: 1/2 MUSTANG | B41: 3 | C41: 1 | D41: =B41-C41 -> 2 | E41: 0 | F41: =D41-E41 -> 2 | G41: 0 | H41: 1 | I41: 0 | J41: 0 | K41: =H41+I41-J41 -> 1 | L41: 5 | M41: 2 | N41: =K41+L41-M41 -> 4 | O41: 0 | P41: 0 | Q41: =N41+P41-O41 -> 4 | R41: 0 | S41: 1 | T41: =Q41+S41-R41 -> 5 | U41: 0 | V41: 1 | W41: 3 | X41: 0 | Y41: 0 | Z41: =W41+X41-Y41 -> 3 | AA41: 0 | AB41: 0 | AC41: =Z41+AA41-AB41 -> 3 | AD41: 0 | AE41: 0 | AF41: =AC41+AD41-AE41 -> 3 | AG41: 0 | AH41: 0 | AI41: =AF41+AG41-AH41 -> 3 | AJ41: 0 | AK41: 0 | AL41: =AI41+AJ41-AK41 -> 3 | AM41: 0 | AN41: 0 | AO41: =AL41+AM41-AN41 -> 3 | AP41: 0 | AQ41: 0 | AR41: =AO41+AP41-AQ41 -> 3 | AS41: 1 | AT41: 1 | AU41: =AR41+AS41-AT41 -> 3 | AV41: 0 | AW41: 1 | AX41: =AU41+AV41-AW41 -> 2 | AY41: 0 | AZ41: 2 | BA41: =AX41+AY41-AZ41 -> 0 | BB41: 3 | BC41: 0 | BD41: =BA41+BB41-BC41 -> 3 | BE41: 0 | BF41: 0 | BG41: =BD41+BE41-BF41 -> 3 | BH41: 0 | BI41: 0 | BJ41: =BG41+BH41-BI41 -> 3 | BK41: 0 | BL41: 0 | BM41: =BJ41+BK41-BL41 -> 3 | BN41: 0 | BO41: =BM41-BN41 -> 3
A42: UND. MUSTANG | B42: 3 | C42: 0 | D42: =B42-C42 -> 3 | E42: 0 | F42: =D42-E42 -> 3 | G42: 11 | H42: 1 | I42: 0 | J42: 0 | K42: =H42+I42-J42 -> 1 | L42: 0 | M42: 7 | N42: =K42+L42-M42 -> -6 | O42: 10 | P42: 0 | Q42: =N42+P42-O42 -> -16 | R42: 5 | S42: 0 | T42: =Q42+S42-R42 -> -21 | U42: 2 | V42: 40 | W42: 39 | X42: 0 | Y42: 5 | Z42: =W42+X42-Y42 -> 34 | AA42: 20 | AB42: 9 | AC42: =Z42+AA42-AB42 -> 45 | AD42: 0 | AE42: 0 | AF42: =AC42+AD42-AE42 -> 45 | AG42: 0 | AH42: 2 | AI42: =AF42+AG42-AH42 -> 43 | AJ42: 0 | AK42: 0 | AL42: =AI42+AJ42-AK42 -> 43 | AM42: 0 | AN42: 0 | AO42: =AL42+AM42-AN42 -> 43 | AP42: 0 | AQ42: 0 | AR42: =AO42+AP42-AQ42 -> 43 | AS42: 0 | AT42: 0 | AU42: =AR42+AS42-AT42 -> 43 | AV42: 0 | AW42: 2 | AX42: =AU42+AV42-AW42 -> 41 | AY42: 0 | AZ42: 16 | BA42: =AX42+AY42-AZ42 -> 25 | BB42: 20 | BC42: 14 | BD42: =BA42+BB42-BC42 -> 31 | BE42: 0 | BF42: 3 | BG42: =BD42+BE42-BF42 -> 28 | BH42: 20 | BI42: 2 | BJ42: =BG42+BH42-BI42 -> 46 | BK42: 0 | BL42: 0 | BM42: =BJ42+BK42-BL42 -> 46 | BN42: 6 | BO42: =BM42-BN42 -> 40
A43: 1/2 LUCKY | B43: 4 | C43: 0 | D43: =B43-C43 -> 4 | E43: 1 | F43: =D43-E43 -> 3 | G43: 0 | H43: 0 | I43: 2 | J43: 4 | K43: =H43+I43-J43 -> -2 | L43: 7 | M43: 0 | N43: =K43+L43-M43 -> 5 | O43: 0 | P43: 0 | Q43: =N43+P43-O43 -> 5 | R43: 0 | S43: 0 | T43: =Q43+S43-R43 -> 5 | U43: 0 | V43: 1 | W43: 2 | X43: 0 | Y43: 1 | Z43: =W43+X43-Y43 -> 1 | AA43: 1 | AB43: 0 | AC43: =Z43+AA43-AB43 -> 2 | AD43: 0 | AE43: 1 | AF43: =AC43+AD43-AE43 -> 1 | AG43: 1 | AH43: 0 | AI43: =AF43+AG43-AH43 -> 2 | AJ43: 0 | AK43: 0 | AL43: =AI43+AJ43-AK43 -> 2 | AM43: 0 | AN43: 1 | AO43: =AL43+AM43-AN43 -> 1 | AP43: 0 | AQ43: 0 | AR43: =AO43+AP43-AQ43 -> 1 | AS43: 1 | AT43: 0 | AU43: =AR43+AS43-AT43 -> 2 | AV43: 0 | AW43: 0 | AX43: =AU43+AV43-AW43 -> 2 | AY43: 0 | AZ43: 0 | BA43: =AX43+AY43-AZ43 -> 2 | BB43: 0 | BC43: 0 | BD43: =BA43+BB43-BC43 -> 2 | BE43: 0 | BF43: 0 | BG43: =BD43+BE43-BF43 -> 2 | BH43: 0 | BI43: 0 | BJ43: =BG43+BH43-BI43 -> 2 | BK43: 0 | BL43: 0 | BM43: =BJ43+BK43-BL43 -> 2 | BN43: 0 | BO43: =BM43-BN43 -> 2
A44: UND. LUCKY | B44: 10 | C44: 4 | D44: =B44-C44 -> 6 | E44: 3 | F44: =D44-E44 -> 3 | G44: 1 | H44: 3 | I44: 0 | J44: 16 | K44: =H44+I44-J44 -> -13 | L44: 0 | M44: 8 | N44: =K44+L44-M44 -> -21 | O44: 7 | P44: 0 | Q44: =N44+P44-O44 -> -28 | R44: 10 | S44: 0 | T44: =Q44+S44-R44 -> -38 | U44: 12 | V44: 40 | W44: 34 | X44: 0 | Y44: 7 | Z44: =W44+X44-Y44 -> 27 | AA44: 20 | AB44: 8 | AC44: =Z44+AA44-AB44 -> 39 | AD44: 0 | AE44: 13 | AF44: =AC44+AD44-AE44 -> 26 | AG44: 0 | AH44: 1 | AI44: 26 | AJ44: 0 | AK44: 12 | AL44: =AI44+AJ44-AK44 -> 14 | AM44: 30 | AN44: 12 | AO44: =AL44+AM44-AN44 -> 32 | AP44: 0 | AQ44: 9 | AR44: =AO44+AP44-AQ44 -> 23 | AS44: 20 | AT44: 11 | AU44: =AR44+AS44-AT44 -> 32 | AV44: 0 | AW44: 13 | AX44: =AU44+AV44-AW44 -> 19 | AY44: 0 | AZ44: 2 | BA44: =AX44+AY44-AZ44 -> 17 | BB44: 0 | BC44: 11 | BD44: =BA44+BB44-BC44 -> 6 | BE44: 0 | BF44: 5 | BG44: =BD44+BE44-BF44 -> 1 | BH44: 20 | BI44: 4 | BJ44: =BG44+BH44-BI44 -> 17 | BK44: 0 | BL44: 0 | BM44: =BJ44+BK44-BL44 -> 17 | BN44: 4 | BO44: =BM44-BN44 -> 13
A45: 1/2 MALBORO ROJO | B45: 4 | C45: 0 | D45: =B45-C45 -> 4 | E45: 0 | F45: =D45-E45 -> 4 | G45: 0 | H45: =F45-G45 -> 4 | I45: 0 | J45: 0 | K45: =H45+I45-J45 -> 4 | L45: 0 | M45: 0 | N45: =K45+L45-M45 -> 4 | O45: 0 | P45: 0 | Q45: =N45+P45-O45 -> 4 | R45: 0 | S45: 0 | T45: =Q45+S45-R45 -> 4 | U45: 0 | V45: 0 | W45: 3 | X45: 0 | Y45: 0 | Z45: =W45+X45-Y45 -> 3 | AA45: 0 | AB45: 0 | AC45: =Z45+AA45-AB45 -> 3 | AD45: 0 | AE45: 0 | AF45: =AC45+AD45-AE45 -> 3 | AG45: 0 | AH45: 0 | AI45: =AF45+AG45-AH45 -> 3 | AJ45: 0 | AK45: 0 | AL45: =AI45+AJ45-AK45 -> 3 | AM45: 0 | AN45: 0 | AO45: =AL45+AM45-AN45 -> 3 | AP45: 0 | AQ45: 0 | AR45: =AO45+AP45-AQ45 -> 3 | AS45: 0 | AT45: 0 | AU45: =AR45+AS45-AT45 -> 3 | AV45: 0 | AW45: 0 | AX45: =AU45+AV45-AW45 -> 3 | AY45: 0 | AZ45: 1 | BA45: =AX45+AY45-AZ45 -> 2 | BB45: 0 | BC45: 0 | BD45: =BA45+BB45-BC45 -> 2 | BE45: 0 | BF45: 0 | BG45: =BD45+BE45-BF45 -> 2 | BH45: 0 | BI45: 0 | BJ45: =BG45+BH45-BI45 -> 2 | BK45: 0 | BL45: 0 | BM45: =BJ45+BK45-BL45 -> 2 | BN45: 0 | BO45: =BM45-BN45 -> 2
...

Sheet GANAN. ENE
A1: PRODUCTO | B1: PRECIO | C1: VR UNIDAD | D1: VR VENTA | E1: VR GANANCIA | F1: 09/01/25 VENTA | G1: 09/01/25 GANANCIA | H1: 10/01/25 VENTA | I1: 10/01/25 GANANCIA | J1: 11/01/25 VENTA | K1: 11/01/25 GANANCIA | L1: 12/01/25 VENTA | M1: 12/01/25 GANANCIA | N1: 13/01/25 VENTA | O1: 13/01/25 GANANCIA | P1: 14/01/25 VENTA | Q1: 14/01/25 GANANCIA | R1: 15/01/25 VENTA | S1: 15/01/25 GANANCIA | T1: 16/01/25 VENTA | U1: 16/01/25 GANANCIA | V1: 17/01/25 VENTA | W1: 17/01/25 GANANCIA | X1: 18/01/25 VENTA | Y1: 18/01/25 GANANCIA | Z1: 19/01/25 VENTA | AA1: 19/01/25 GANANCIA | AB1: 20/01/25 VENTA | AC1: 20/01/25 GANANCIA | AD1: 21/01/25 VENTA | AE1: 21/01/25 GANANCIA | AF1: 22/01/25 VENTA | AG1: 22/01/25 GANANCIA | AH1: 23/01/25 VENTA | AI1: 23/01/25 GANANCIA | AJ1: 24/01/25 VENTA | AK1: 24/01/25 GANANCIA | AL1: 25/01/25 VENTA | AM1: 25/01/25 GANANCIA | AN1: 26/01/25 VENTA | AO1: 26/01/25 GANANCIA | AP1: 27/01/25 VENTA | AQ1: 27/01/25 GANANCIA | AR1: 28/01/25 VENTA | AS1: 28/01/25 GANANCIA | AT1: 29/01/25 VENTA | AU1: 29/01/25 GANANCIA | AV1: 30/01/25 VENTA | AW1: 30/01/25 GANANCIA | AX1: 31/01/25 VENTA | AY1: 31/01/25 GANANCIA
